Workbook
Name painel: 'PAINEL DE STATUS COBRANÇAS'!$1:$1048576
Name TABELACOBRAN: 'BASE COBRANÇAS'!$A$3:$T$275

Sheet BASE COBRANÇAS
A1: ⚡ BASE COBRANÇAS
A2: 🔄 Como atualizar: extraia relatorios de DOCUMENTOS (APISULLOG/RESULTADOS/DOCUMENTOS) 3 dias no filtro " - "LOCALIZAÇÃO DE CARGA (APISULLOG/OPERAÇÃO/LOCALIZAÇÃO DE CARGA) 3 dias no filtro" - "VISÃO LOGISTICA (APISULLOG/OPERAÇÃO/VISÃO LOGISTICA) - 3 dias no filtro " Cole os novos dados nas abas "DOCUMENTOS" e "LOCALIZAÇÃO DE CARGA" - "VISÃO LOGISTICA" (mantendo cabeçalhos na linha 1)
A3: DATA PROGRAMAÇÃO CHEGADA | B3: Nº Pedido / Doc. | C3: ⚠ ALERTA COBRANÇA | D3: Observação (Situação da viagem) | E3: CARREGAMENTO | F3: Transportadora | G3: Origem | H3: Status | I3: STATUS SMP | J3: Placa | K3: Valor (R$) | L3: Prev. Início com base na data entrega (LOCALIZAÇÃO) | M3: Chegada Filial (DOCUMENTOS) | N3: ⏰ Hora Limite p/ Chegada (Lib -1h) | O3: Data Entrega (LOCALIZAÇÃO) | P3: Prev. Online (Atualizada) | Q3: Destino | R3: Cliente Final | S3: Localização do veiculo | T3: Cidade/UF Destino
A4: =IF(M4="","",INT(M4)) -> 46157 | B4: {=_xlfn._xlws.FILTER( 'LOCALIZAÇÃO DE CARGA'!A2:A1702, ( (('LOCALIZAÇÃO DE CARGA'!F2:F1702="não iniciado")+ ('LOCALIZAÇÃO DE CARGA'!F2:F1702="Andamento"))>0 ) * (ISNUMBER(VALUE('LOCALIZAÇÃO DE CARGA'!A2:A1702))), "Sem pedidos" )} -> 6022063 | C4: =IFERROR( IF(B4="","", IF(I4="Encerrada", "VERIFICAR SMP EM ANDAMENTO", IF(VALUE(SUBSTITUTE(K4,".",""))<100000, "DESCONSIDERA, VALOR NÃO RASTREADO", IF(AND(I4="EM VIAGEM",ISNUMBER(FIND("CAJAMAR/SP",S4))), IF(E4="Patio", "NA PENSKE - COM SMP - AGUARDANDO CARREGAMENTO", "NA PENSKE - COM SMP - AGUARDANDO SAÍDA"), IF(AND(I4="Pré-SMP",ISNUMBER(FIND("CAJAMAR/SP",S4))), IF(E4="Patio", "NA PENSKE - PRÉ-SMP - AGUARDANDO CARREGAMENTO", "NA PENSKE - PRÉ-SMP - AGUARDANDO SAÍDA"), IF(AND(I4="EM VIAGEM",ISNUMBER(FIND("ITAPOA/SC",S4))), "NA CLIF - COM SMP - AGUARDANDO SAÍDA", IF(AND(I4="Pré-SMP",ISNUMBER(FIND("ITAPOA/SC",S4))), "NA CLIF - PRÉ-SMP - AGUARDANDO SAÍDA", IF(I4="EM VIAGEM", "EM VIAGEM", IF(OR(L4="",N4=""), IF(I4="EM VIAGEM","SEM PREVISAO - COM SMP", IF(I4="Pré-SMP","SEM PREVISAO - PRÉ-SMP", "SEM PREVISAO - SEM SMP")), IF(M4>L4, IF(NOW()>N4, IF(E4="Finalizado", IF(I4="EM VIAGEM","CARREGADO - COM SMP", IF(I4="Pré-SMP","CARREGADO - PRÉ-SMP", "CARREGADO - SEM SMP")), IF(I4="EM VIAGEM","ATRASADO CARREGAMENTO - COM SMP - VERIFICAR AGENDAMENTO", IF(I4="Pré-SMP","ATRASADO CARREGAMENTO - PRÉ-SMP - VERIFICAR AGENDAMENTO", "ATRASADO CARREGAMENTO - SEM SMP - VERIFICAR AGENDAMENTO"))), IF(NOW()>L4, IF(I4="EM VIAGEM","ATRASADO ENTREGA - COM SMP - VERIFICAR AGENDAMENTO", IF(I4="Pré-SMP","ATRASADO ENTREGA - PRÉ-SMP - VERIFICAR AGENDAMENTO", "ATRASADO ENTREGA - SEM SMP - VERIFICAR AGENDAMENTO")), "OK NO PRAZO - VERIFICAR AGENDAMENTO")), IF(NOW()>L4, IF(I4="EM VIAGEM","ATRASADO ENTREGA - COM SMP", IF(I4="Pré-SMP","ATRASADO ENTREGA - PRÉ-SMP", "ATRASADO ENTREGA - SEM SMP")), IF(NOW()>N4, IF(E4="Finalizado", IF(I4="EM VIAGEM","CARREGADO - COM SMP", IF(I4="Pré-SMP","CARREGADO - PRÉ-SMP", "CARREGADO - SEM SMP")), IF(I4="EM VIAGEM","ATRASADO CARREGAMENTO - COM SMP", IF(I4="Pré-SMP","ATRASADO CARREGAMENTO - PRÉ-SMP", "ATRASADO CARREGAMENTO - SEM SMP"))), IF(L4-NOW()<=1, "ATENCAO - PROXIMO", "OK - NO PRAZO" ))))))))))))),"") -> EM VIAGEM | E4: =IFERROR( IF( _xlfn.XLOOKUP( B4, 'LOCALIZAÇÃO DE CARGA'!$A$2:$A$702, 'LOCALIZAÇÃO DE CARGA'!$D$2:$D$702 )="", "", _xlfn.XLOOKUP( B4, 'LOCALIZAÇÃO DE CARGA'!$A$2:$A$702, 'LOCALIZAÇÃO DE CARGA'!$D$2:$D$702 ) ), "" ) -> Saida do WH | F4: =IFERROR( IF( _xlfn.XLOOKUP( B4, 'LOCALIZAÇÃO DE CARGA'!$A$2:$A$702, 'LOCALIZAÇÃO DE CARGA'!$H$2:$H$702 )="", "", _xlfn.XLOOKUP( B4, 'LOCALIZAÇÃO DE CARGA'!$A$2:$A$702, 'LOCALIZAÇÃO DE CARGA'!$H$2:$H$702 ) ), "" ) -> TR RAMTHUN | G4: =IFERROR( IF( _xlfn.XLOOKUP( B4, 'LOCALIZAÇÃO DE CARGA'!$A$2:$A$702, 'LOCALIZAÇÃO DE CARGA'!$I$2:$I$702 )="", "", _xlfn.XLOOKUP( B4, 'LOCALIZAÇÃO DE CARGA'!$A$2:$A$702, 'LOCALIZAÇÃO DE CARGA'!$I$2:$I$702 ) ), "" ) -> LGCAJ | H4: =IFERROR( IF( _xlfn.XLOOKUP( B4, 'LOCALIZAÇÃO DE CARGA'!$A$2:$A$702, 'LOCALIZAÇÃO DE CARGA'!$F$2:$F$702 )="", "", _xlfn.XLOOKUP( B4, 'LOCALIZAÇÃO DE CARGA'!$A$2:$A$702, 'LOCALIZAÇÃO DE CARGA'!$F$2:$F$702 ) ), "" ) -> Andamento | I4: {=IFERROR( IF( OR( INDEX( 'VISÃO LOGISTICA'!$C$2:$C$525, MATCH( TRUE, ISNUMBER(FIND(B4,'VISÃO LOGISTICA'!$A$2:$A$525)), 0 ) )="Em espera", INDEX( 'VISÃO LOGISTICA'!$C$2:$C$525, MATCH( TRUE, ISNUMBER(FIND(B4,'VISÃO LOGISTICA'!$A$2:$A$525)), 0 ) )="" ), "", INDEX( 'VISÃO LOGISTICA'!$C$2:$C$525, MATCH( TRUE, ISNUMBER(FIND(B4,'VISÃO LOGISTICA'!$A$2:$A$525)), 0 ) ) ), "" )} -> Em Viagem | J4: {=IFERROR( IF( OR( INDEX( 'VISÃO LOGISTICA'!$C$2:$C$2000, MATCH( TRUE, ISNUMBER(FIND(B4,'VISÃO LOGISTICA'!$A$2:$A$2000)), 0 ) )="Em espera", INDEX( 'VISÃO LOGISTICA'!$C$2:$C$2000, MATCH( TRUE, ISNUMBER(FIND(B4,'VISÃO LOGISTICA'!$A$2:$A$2000)), 0 ) )="" ), "", INDEX( 'VISÃO LOGISTICA'!$D$2:$D$2000, MATCH( TRUE, ISNUMBER(FIND(B4,'VISÃO LOGISTICA'!$A$2:$A$2000)), 0 ) ) ), "" )} -> QHG5H17 | K4: =IFERROR( IF( _xlfn.XLOOKUP( B4, 'LOCALIZAÇÃO DE CARGA'!$A$2:$A$702, 'LOCALIZAÇÃO DE CARGA'!$E$2:$E$702)="", "", _xlfn.XLOOKUP( B4, 'LOCALIZAÇÃO DE CARGA'!$A$2:$A$702, 'LOCALIZAÇÃO DE CARGA'!$E$2:$E$702) ), "" ) -> 1341079.3 | L4: {=IFERROR( _xlfn.LET( _xlpm.res,_xlfn.XLOOKUP(B4,'LOCALIZAÇÃO DE CARGA'!$A$2:$A$2000,'LOCALIZAÇÃO DE CARGA'!$G$2:$G$2000), IF(_xlpm.res="","",_xlpm.res) ), "" )} -> 46157.333 | M4: {=IFERROR( _xlfn.LET( _xlpm.load,_xlfn.XLOOKUP(B4,'LOCALIZAÇÃO DE CARGA'!$A$2:$A$2000,'LOCALIZAÇÃO DE CARGA'!$A$2:$A$2000), _xlpm.res,_xlfn.XLOOKUP(_xlpm.load,DOCUMENTOS!$A$2:$A$2000,DOCUMENTOS!$D$2:$D$2000), IF(_xlpm.res="","",_xlpm.res) ), "" )} -> 46157.333 | N4: =IFERROR(IF(M4="","",M4-TIME(1,0,0)),"") -> 46157.292 | O4: {=IFERROR( _xlfn.LET( _xlpm.res,_xlfn.XLOOKUP(B4,'LOCALIZAÇÃO DE CARGA'!$A$2:$A$2000,'LOCALIZAÇÃO DE CARGA'!$S$2:$S$2000), IF(_xlpm.res="","",_xlpm.res) ), "" )} -> 46161.292 | P4: {=IFERROR( _xlfn.LET( _xlpm.res,_xlfn.XLOOKUP(B4,'LOCALIZAÇÃO DE CARGA'!$A$2:$A$702,'LOCALIZAÇÃO DE CARGA'!$T$2:$T$702), IF(_xlpm.res="","",_xlpm.res) ), "" )} -> 46158.892 | Q4: =IFERROR( IF( _xlfn.XLOOKUP( B4, 'LOCALIZAÇÃO DE CARGA'!$A$2:$A$702, 'LOCALIZAÇÃO DE CARGA'!$K$2:$K$702 )="", "", _xlfn.XLOOKUP( B4, 'LOCALIZAÇÃO DE CARGA'!$A$2:$A$702, 'LOCALIZAÇÃO DE CARGA'!$K$2:$K$702 ) ), "" ) -> FUJIOKA ELETRO IMAGEM S/A - 74675690 | R4: =IF(Q4="","",TRIM(IFERROR(LEFT(LEFT(Q4,FIND(" - ",Q4)-1),FIND("(",LEFT(Q4,FIND(" - ",Q4)-1))-1),LEFT(Q4,FIND(" - ",Q4)-1)))) -> FUJIOKA ELETRO IMAGEM S/A | S4: {=IF(B4="","",IFERROR( INDEX( 'VISÃO LOGISTICA'!$L$2:$L$525, MATCH( TRUE, ISNUMBER(FIND(B4,'VISÃO LOGISTICA'!$A$2:$A$525)), 0 ) ), "" ))} -> RODOVIA ANHANGUERA, RIBEIRAO PRETO/SP/BRASIL (0,01 Km) | T4: =IFERROR( _xlfn.LET( _xlpm.res,_xlfn.XLOOKUP(B4,'LOCALIZAÇÃO DE CARGA'!$A$2:$A$702,'LOCALIZAÇÃO DE CARGA'!$R$2:$R$702), IF(_xlpm.res="","",_xlpm.res) ), "" ) -> GOIANIA/GO/BRASIL
A5: =IF(M5="","",INT(M5)) -> 46157 | B5: 6022062 | C5: =IFERROR( IF(B5="","", IF(I5="Encerrada", "VERIFICAR SMP EM ANDAMENTO", IF(VALUE(SUBSTITUTE(K5,".",""))<100000, "DESCONSIDERA, VALOR NÃO RASTREADO", IF(AND(I5="EM VIAGEM",ISNUMBER(FIND("CAJAMAR/SP",S5))), IF(E5="Patio", "NA PENSKE - COM SMP - AGUARDANDO CARREGAMENTO", "NA PENSKE - COM SMP - AGUARDANDO SAÍDA"), IF(AND(I5="Pré-SMP",ISNUMBER(FIND("CAJAMAR/SP",S5))), IF(E5="Patio", "NA PENSKE - PRÉ-SMP - AGUARDANDO CARREGAMENTO", "NA PENSKE - PRÉ-SMP - AGUARDANDO SAÍDA"), IF(AND(I5="EM VIAGEM",ISNUMBER(FIND("ITAPOA/SC",S5))), "NA CLIF - COM SMP - AGUARDANDO SAÍDA", IF(AND(I5="Pré-SMP",ISNUMBER(FIND("ITAPOA/SC",S5))), "NA CLIF - PRÉ-SMP - AGUARDANDO SAÍDA", IF(I5="EM VIAGEM", "EM VIAGEM", IF(OR(L5="",N5=""), IF(I5="EM VIAGEM","SEM PREVISAO - COM SMP", IF(I5="Pré-SMP","SEM PREVISAO - PRÉ-SMP", "SEM PREVISAO - SEM SMP")), IF(M5>L5, IF(NOW()>N5, IF(E5="Finalizado", IF(I5="EM VIAGEM","CARREGADO - COM SMP", IF(I5="Pré-SMP","CARREGADO - PRÉ-SMP", "CARREGADO - SEM SMP")), IF(I5="EM VIAGEM","ATRASADO CARREGAMENTO - COM SMP - VERIFICAR AGENDAMENTO", IF(I5="Pré-SMP","ATRASADO CARREGAMENTO - PRÉ-SMP - VERIFICAR AGENDAMENTO", "ATRASADO CARREGAMENTO - SEM SMP - VERIFICAR AGENDAMENTO"))), IF(NOW()>L5, IF(I5="EM VIAGEM","ATRASADO ENTREGA - COM SMP - VERIFICAR AGENDAMENTO", IF(I5="Pré-SMP","ATRASADO ENTREGA - PRÉ-SMP - VERIFICAR AGENDAMENTO", "ATRASADO ENTREGA - SEM SMP - VERIFICAR AGENDAMENTO")), "OK NO PRAZO - VERIFICAR AGENDAMENTO")), IF(NOW()>L5, IF(I5="EM VIAGEM","ATRASADO ENTREGA - COM SMP", IF(I5="Pré-SMP","ATRASADO ENTREGA - PRÉ-SMP", "ATRASADO ENTREGA - SEM SMP")), IF(NOW()>N5, IF(E5="Finalizado", IF(I5="EM VIAGEM","CARREGADO - COM SMP", IF(I5="Pré-SMP","CARREGADO - PRÉ-SMP", "CARREGADO - SEM SMP")), IF(I5="EM VIAGEM","ATRASADO CARREGAMENTO - COM SMP", IF(I5="Pré-SMP","ATRASADO CARREGAMENTO - PRÉ-SMP", "ATRASADO CARREGAMENTO - SEM SMP"))), IF(L5-NOW()<=1, "ATENCAO - PROXIMO", "OK - NO PRAZO" ))))))))))))),"") -> EM VIAGEM | E5: =IFERROR( IF( _xlfn.XLOOKUP( B5, 'LOCALIZAÇÃO DE CARGA'!$A$2:$A$702, 'LOCALIZAÇÃO DE CARGA'!$D$2:$D$702 )="", "", _xlfn.XLOOKUP( B5, 'LOCALIZAÇÃO DE CARGA'!$A$2:$A$702, 'LOCALIZAÇÃO DE CARGA'!$D$2:$D$702 ) ), "" ) -> Saida do WH | F5: =IFERROR( IF( _xlfn.XLOOKUP( B5, 'LOCALIZAÇÃO DE CARGA'!$A$2:$A$702, 'LOCALIZAÇÃO DE CARGA'!$H$2:$H$702 )="", "", _xlfn.XLOOKUP( B5, 'LOCALIZAÇÃO DE CARGA'!$A$2:$A$702, 'LOCALIZAÇÃO DE CARGA'!$H$2:$H$702 ) ), "" ) -> TR RAMTHUN | G5: =IFERROR( IF( _xlfn.XLOOKUP( B5, 'LOCALIZAÇÃO DE CARGA'!$A$2:$A$702, 'LOCALIZAÇÃO DE CARGA'!$I$2:$I$702 )="", "", _xlfn.XLOOKUP( B5, 'LOCALIZAÇÃO DE CARGA'!$A$2:$A$702, 'LOCALIZAÇÃO DE CARGA'!$I$2:$I$702 ) ), "" ) -> LGCAJ | H5: =IFERROR( IF( _xlfn.XLOOKUP( B5, 'LOCALIZAÇÃO DE CARGA'!$A$2:$A$702, 'LOCALIZAÇÃO DE CARGA'!$F$2:$F$702 )="", "", _xlfn.XLOOKUP( B5, 'LOCALIZAÇÃO DE CARGA'!$A$2:$A$702, 'LOCALIZAÇÃO DE CARGA'!$F$2:$F$702 ) ), "" ) -> Andamento | I5: {=IFERROR( IF( INDEX( 'VISÃO LOGISTICA'!$C$2:$C$525, MATCH( TRUE, ISNUMBER(FIND(B5,'VISÃO LOGISTICA'!$A$2:$A$525)), 0 ) )="Em espera", "", INDEX( 'VISÃO LOGISTICA'!$C$2:$C$525, MATCH( TRUE, ISNUMBER(FIND(B5,'VISÃO LOGISTICA'!$A$2:$A$525)), 0 ) ) ), "" )} -> Em Viagem | J5: {=IFERROR( IF( OR( INDEX( 'VISÃO LOGISTICA'!$C$2:$C$2000, MATCH( TRUE, ISNUMBER(FIND(B5,'VISÃO LOGISTICA'!$A$2:$A$2000)), 0 ) )="Em espera", INDEX( 'VISÃO LOGISTICA'!$C$2:$C$2000, MATCH( TRUE, ISNUMBER(FIND(B5,'VISÃO LOGISTICA'!$A$2:$A$2000)), 0 ) )="" ), "", INDEX( 'VISÃO LOGISTICA'!$D$2:$D$2000, MATCH( TRUE, ISNUMBER(FIND(B5,'VISÃO LOGISTICA'!$A$2:$A$2000)), 0 ) ) ), "" )} -> QHG5H17 | K5: =IFERROR( IF( _xlfn.XLOOKUP( B5, 'LOCALIZAÇÃO DE CARGA'!$A$2:$A$702, 'LOCALIZAÇÃO DE CARGA'!$E$2:$E$702)="", "", _xlfn.XLOOKUP( B5, 'LOCALIZAÇÃO DE CARGA'!$A$2:$A$702, 'LOCALIZAÇÃO DE CARGA'!$E$2:$E$702) ), "" ) -> 1341079.3 | L5: {=IFERROR( _xlfn.LET( _xlpm.res,_xlfn.XLOOKUP(B5,'LOCALIZAÇÃO DE CARGA'!$A$2:$A$2000,'LOCALIZAÇÃO DE CARGA'!$G$2:$G$2000), IF(_xlpm.res="","",_xlpm.res) ), "" )} -> 46157.333 | M5: {=IFERROR( _xlfn.LET( _xlpm.load,_xlfn.XLOOKUP(B5,'LOCALIZAÇÃO DE CARGA'!$A$2:$A$2000,'LOCALIZAÇÃO DE CARGA'!$A$2:$A$2000), _xlpm.res,_xlfn.XLOOKUP(_xlpm.load,DOCUMENTOS!$A$2:$A$2000,DOCUMENTOS!$D$2:$D$2000), IF(_xlpm.res="","",_xlpm.res) ), "" )} -> 46157.333 | N5: =IFERROR(IF(M5="","",M5-TIME(1,0,0)),"") -> 46157.292 | O5: {=IFERROR( _xlfn.LET( _xlpm.res,_xlfn.XLOOKUP(B5,'LOCALIZAÇÃO DE CARGA'!$A$2:$A$2000,'LOCALIZAÇÃO DE CARGA'!$S$2:$S$2000), IF(_xlpm.res="","",_xlpm.res) ), "" )} -> 46161.292 | P5: {=IFERROR( _xlfn.LET( _xlpm.res,_xlfn.XLOOKUP(B5,'LOCALIZAÇÃO DE CARGA'!$A$2:$A$702,'LOCALIZAÇÃO DE CARGA'!$T$2:$T$702), IF(_xlpm.res="","",_xlpm.res) ), "" )} -> 46158.892 | Q5: =IFERROR( IF( _xlfn.XLOOKUP( B5, 'LOCALIZAÇÃO DE CARGA'!$A$2:$A$702, 'LOCALIZAÇÃO DE CARGA'!$K$2:$K$702 )="", "", _xlfn.XLOOKUP( B5, 'LOCALIZAÇÃO DE CARGA'!$A$2:$A$702, 'LOCALIZAÇÃO DE CARGA'!$K$2:$K$702 ) ), "" ) -> FUJIOKA ELETRO IMAGEM S/A - 74675690 | R5: =IF(Q5="","",TRIM(IFERROR(LEFT(LEFT(Q5,FIND(" - ",Q5)-1),FIND("(",LEFT(Q5,FIND(" - ",Q5)-1))-1),LEFT(Q5,FIND(" - ",Q5)-1)))) -> FUJIOKA ELETRO IMAGEM S/A | S5: {=IF(B5="","",IFERROR( INDEX( 'VISÃO LOGISTICA'!$L$2:$L$525, MATCH( TRUE, ISNUMBER(FIND(B5,'VISÃO LOGISTICA'!$A$2:$A$525)), 0 ) ), "" ))} -> RODOVIA ANHANGUERA, RIBEIRAO PRETO/SP/BRASIL (0,01 Km) | T5: =IFERROR( _xlfn.LET( _xlpm.res,_xlfn.XLOOKUP(B5,'LOCALIZAÇÃO DE CARGA'!$A$2:$A$702,'LOCALIZAÇÃO DE CARGA'!$R$2:$R$702), IF(_xlpm.res="","",_xlpm.res) ), "" ) -> GOIANIA/GO/BRASIL
A6: =IF(M6="","",INT(M6)) -> 46157 | B6: 6022065 | C6: =IFERROR( IF(B6="","", IF(I6="Encerrada", "VERIFICAR SMP EM ANDAMENTO", IF(VALUE(SUBSTITUTE(K6,".",""))<100000, "DESCONSIDERA, VALOR NÃO RASTREADO", IF(AND(I6="EM VIAGEM",ISNUMBER(FIND("CAJAMAR/SP",S6))), IF(E6="Patio", "NA PENSKE - COM SMP - AGUARDANDO CARREGAMENTO", "NA PENSKE - COM SMP - AGUARDANDO SAÍDA"), IF(AND(I6="Pré-SMP",ISNUMBER(FIND("CAJAMAR/SP",S6))), IF(E6="Patio", "NA PENSKE - PRÉ-SMP - AGUARDANDO CARREGAMENTO", "NA PENSKE - PRÉ-SMP - AGUARDANDO SAÍDA"), IF(AND(I6="EM VIAGEM",ISNUMBER(FIND("ITAPOA/SC",S6))), "NA CLIF - COM SMP - AGUARDANDO SAÍDA", IF(AND(I6="Pré-SMP",ISNUMBER(FIND("ITAPOA/SC",S6))), "NA CLIF - PRÉ-SMP - AGUARDANDO SAÍDA", IF(I6="EM VIAGEM", "EM VIAGEM", IF(OR(L6="",N6=""), IF(I6="EM VIAGEM","SEM PREVISAO - COM SMP", IF(I6="Pré-SMP","SEM PREVISAO - PRÉ-SMP", "SEM PREVISAO - SEM SMP")), IF(M6>L6, IF(NOW()>N6, IF(E6="Finalizado", IF(I6="EM VIAGEM","CARREGADO - COM SMP", IF(I6="Pré-SMP","CARREGADO - PRÉ-SMP", "CARREGADO - SEM SMP")), IF(I6="EM VIAGEM","ATRASADO CARREGAMENTO - COM SMP - VERIFICAR AGENDAMENTO", IF(I6="Pré-SMP","ATRASADO CARREGAMENTO - PRÉ-SMP - VERIFICAR AGENDAMENTO", "ATRASADO CARREGAMENTO - SEM SMP - VERIFICAR AGENDAMENTO"))), IF(NOW()>L6, IF(I6="EM VIAGEM","ATRASADO ENTREGA - COM SMP - VERIFICAR AGENDAMENTO", IF(I6="Pré-SMP","ATRASADO ENTREGA - PRÉ-SMP - VERIFICAR AGENDAMENTO", "ATRASADO ENTREGA - SEM SMP - VERIFICAR AGENDAMENTO")), "OK NO PRAZO - VERIFICAR AGENDAMENTO")), IF(NOW()>L6, IF(I6="EM VIAGEM","ATRASADO ENTREGA - COM SMP", IF(I6="Pré-SMP","ATRASADO ENTREGA - PRÉ-SMP", "ATRASADO ENTREGA - SEM SMP")), IF(NOW()>N6, IF(E6="Finalizado", IF(I6="EM VIAGEM","CARREGADO - COM SMP", IF(I6="Pré-SMP","CARREGADO - PRÉ-SMP", "CARREGADO - SEM SMP")), IF(I6="EM VIAGEM","ATRASADO CARREGAMENTO - COM SMP", IF(I6="Pré-SMP","ATRASADO CARREGAMENTO - PRÉ-SMP", "ATRASADO CARREGAMENTO - SEM SMP"))), IF(L6-NOW()<=1, "ATENCAO - PROXIMO", "OK - NO PRAZO" ))))))))))))),"") -> EM VIAGEM | E6: =IFERROR( IF( _xlfn.XLOOKUP( B6, 'LOCALIZAÇÃO DE CARGA'!$A$2:$A$702, 'LOCALIZAÇÃO DE CARGA'!$D$2:$D$702 )="", "", _xlfn.XLOOKUP( B6, 'LOCALIZAÇÃO DE CARGA'!$A$2:$A$702, 'LOCALIZAÇÃO DE CARGA'!$D$2:$D$702 ) ), "" ) -> Saida do WH | F6: =IFERROR( IF( _xlfn.XLOOKUP( B6, 'LOCALIZAÇÃO DE CARGA'!$A$2:$A$702, 'LOCALIZAÇÃO DE CARGA'!$H$2:$H$702 )="", "", _xlfn.XLOOKUP( B6, 'LOCALIZAÇÃO DE CARGA'!$A$2:$A$702, 'LOCALIZAÇÃO DE CARGA'!$H$2:$H$702 ) ), "" ) -> LX PANTOS | G6: =IFERROR( IF( _xlfn.XLOOKUP( B6, 'LOCALIZAÇÃO DE CARGA'!$A$2:$A$702, 'LOCALIZAÇÃO DE CARGA'!$I$2:$I$702 )="", "", _xlfn.XLOOKUP( B6, 'LOCALIZAÇÃO DE CARGA'!$A$2:$A$702, 'LOCALIZAÇÃO DE CARGA'!$I$2:$I$702 ) ), "" ) -> LGCAJ | H6: =IFERROR( IF( _xlfn.XLOOKUP( B6, 'LOCALIZAÇÃO DE CARGA'!$A$2:$A$702, 'LOCALIZAÇÃO DE CARGA'!$F$2:$F$702 )="", "", _xlfn.XLOOKUP( B6, 'LOCALIZAÇÃO DE CARGA'!$A$2:$A$702, 'LOCALIZAÇÃO DE CARGA'!$F$2:$F$702 ) ), "" ) -> Andamento | I6: {=IFERROR( IF( INDEX( 'VISÃO LOGISTICA'!$C$2:$C$525, MATCH( TRUE, ISNUMBER(FIND(B6,'VISÃO LOGISTICA'!$A$2:$A$525)), 0 ) )="Em espera", "", INDEX( 'VISÃO LOGISTICA'!$C$2:$C$525, MATCH( TRUE, ISNUMBER(FIND(B6,'VISÃO LOGISTICA'!$A$2:$A$525)), 0 ) ) ), "" )} -> Em Viagem | J6: {=IFERROR( IF( OR( INDEX( 'VISÃO LOGISTICA'!$C$2:$C$2000, MATCH( TRUE, ISNUMBER(FIND(B6,'VISÃO LOGISTICA'!$A$2:$A$2000)), 0 ) )="Em espera", INDEX( 'VISÃO LOGISTICA'!$C$2:$C$2000, MATCH( TRUE, ISNUMBER(FIND(B6,'VISÃO LOGISTICA'!$A$2:$A$2000)), 0 ) )="" ), "", INDEX( 'VISÃO LOGISTICA'!$D$2:$D$2000, MATCH( TRUE, ISNUMBER(FIND(B6,'VISÃO LOGISTICA'!$A$2:$A$2000)), 0 ) ) ), "" )} -> NVQ2B29 | K6: =IFERROR( IF( _xlfn.XLOOKUP( B6, 'LOCALIZAÇÃO DE CARGA'!$A$2:$A$702, 'LOCALIZAÇÃO DE CARGA'!$E$2:$E$702)="", "", _xlfn.XLOOKUP( B6, 'LOCALIZAÇÃO DE CARGA'!$A$2:$A$702, 'LOCALIZAÇÃO DE CARGA'!$E$2:$E$702) ), "" ) -> 1335206 | L6: {=IFERROR( _xlfn.LET( _xlpm.res,_xlfn.XLOOKUP(B6,'LOCALIZAÇÃO DE CARGA'!$A$2:$A$2000,'LOCALIZAÇÃO DE CARGA'!$G$2:$G$2000), IF(_xlpm.res="","",_xlpm.res) ), "" )} -> 46160.174 | M6: {=IFERROR( _xlfn.LET( _xlpm.load,_xlfn.XLOOKUP(B6,'LOCALIZAÇÃO DE CARGA'!$A$2:$A$2000,'LOCALIZAÇÃO DE CARGA'!$A$2:$A$2000), _xlpm.res,_xlfn.XLOOKUP(_xlpm.load,DOCUMENTOS!$A$2:$A$2000,DOCUMENTOS!$D$2:$D$2000), IF(_xlpm.res="","",_xlpm.res) ), "" )} -> 46157.833 | N6: =IFERROR(IF(M6="","",M6-TIME(1,0,0)),"") -> 46157.792 | O6: {=IFERROR( _xlfn.LET( _xlpm.res,_xlfn.XLOOKUP(B6,'LOCALIZAÇÃO DE CARGA'!$A$2:$A$2000,'LOCALIZAÇÃO DE CARGA'!$S$2:$S$2000), IF(_xlpm.res="","",_xlpm.res) ), "" )} -> 46161.292 | P6: {=IFERROR( _xlfn.LET( _xlpm.res,_xlfn.XLOOKUP(B6,'LOCALIZAÇÃO DE CARGA'!$A$2:$A$702,'LOCALIZAÇÃO DE CARGA'!$T$2:$T$702), IF(_xlpm.res="","",_xlpm.res) ), "" )} -> 46158.843 | Q6: =IFERROR( IF( _xlfn.XLOOKUP( B6, 'LOCALIZAÇÃO DE CARGA'!$A$2:$A$702, 'LOCALIZAÇÃO DE CARGA'!$K$2:$K$702 )="", "", _xlfn.XLOOKUP( B6, 'LOCALIZAÇÃO DE CARGA'!$A$2:$A$702, 'LOCALIZAÇÃO DE CARGA'!$K$2:$K$702 ) ), "" ) -> FUJIOKA ELETRO IMAGEM S/A - 74675690 | R6: =IF(Q6="","",TRIM(IFERROR(LEFT(LEFT(Q6,FIND(" - ",Q6)-1),FIND("(",LEFT(Q6,FIND(" - ",Q6)-1))-1),LEFT(Q6,FIND(" - ",Q6)-1)))) -> FUJIOKA ELETRO IMAGEM S/A | S6: {=IF(B6="","",IFERROR( INDEX( 'VISÃO LOGISTICA'!$L$2:$L$525, MATCH( TRUE, ISNUMBER(FIND(B6,'VISÃO LOGISTICA'!$A$2:$A$525)), 0 ) ), "" ))} -> RODOVIA ANHANGUERA, ORLANDIA/SP/BRASIL (4,98 Km) | T6: =IFERROR( _xlfn.LET( _xlpm.res,_xlfn.XLOOKUP(B6,'LOCALIZAÇÃO DE CARGA'!$A$2:$A$702,'LOCALIZAÇÃO DE CARGA'!$R$2:$R$702), IF(_xlpm.res="","",_xlpm.res) ), "" ) -> GOIANIA/GO/BRASIL
A7: =IF(M7="","",INT(M7)) -> 46157 | B7: 6022064 | C7: =IFERROR( IF(B7="","", IF(I7="Encerrada", "VERIFICAR SMP EM ANDAMENTO", IF(VALUE(SUBSTITUTE(K7,".",""))<100000, "DESCONSIDERA, VALOR NÃO RASTREADO", IF(AND(I7="EM VIAGEM",ISNUMBER(FIND("CAJAMAR/SP",S7))), IF(E7="Patio", "NA PENSKE - COM SMP - AGUARDANDO CARREGAMENTO", "NA PENSKE - COM SMP - AGUARDANDO SAÍDA"), IF(AND(I7="Pré-SMP",ISNUMBER(FIND("CAJAMAR/SP",S7))), IF(E7="Patio", "NA PENSKE - PRÉ-SMP - AGUARDANDO CARREGAMENTO", "NA PENSKE - PRÉ-SMP - AGUARDANDO SAÍDA"), IF(AND(I7="EM VIAGEM",ISNUMBER(FIND("ITAPOA/SC",S7))), "NA CLIF - COM SMP - AGUARDANDO SAÍDA", IF(AND(I7="Pré-SMP",ISNUMBER(FIND("ITAPOA/SC",S7))), "NA CLIF - PRÉ-SMP - AGUARDANDO SAÍDA", IF(I7="EM VIAGEM", "EM VIAGEM", IF(OR(L7="",N7=""), IF(I7="EM VIAGEM","SEM PREVISAO - COM SMP", IF(I7="Pré-SMP","SEM PREVISAO - PRÉ-SMP", "SEM PREVISAO - SEM SMP")), IF(M7>L7, IF(NOW()>N7, IF(E7="Finalizado", IF(I7="EM VIAGEM","CARREGADO - COM SMP", IF(I7="Pré-SMP","CARREGADO - PRÉ-SMP", "CARREGADO - SEM SMP")), IF(I7="EM VIAGEM","ATRASADO CARREGAMENTO - COM SMP - VERIFICAR AGENDAMENTO", IF(I7="Pré-SMP","ATRASADO CARREGAMENTO - PRÉ-SMP - VERIFICAR AGENDAMENTO", "ATRASADO CARREGAMENTO - SEM SMP - VERIFICAR AGENDAMENTO"))), IF(NOW()>L7, IF(I7="EM VIAGEM","ATRASADO ENTREGA - COM SMP - VERIFICAR AGENDAMENTO", IF(I7="Pré-SMP","ATRASADO ENTREGA - PRÉ-SMP - VERIFICAR AGENDAMENTO", "ATRASADO ENTREGA - SEM SMP - VERIFICAR AGENDAMENTO")), "OK NO PRAZO - VERIFICAR AGENDAMENTO")), IF(NOW()>L7, IF(I7="EM VIAGEM","ATRASADO ENTREGA - COM SMP", IF(I7="Pré-SMP","ATRASADO ENTREGA - PRÉ-SMP", "ATRASADO ENTREGA - SEM SMP")), IF(NOW()>N7, IF(E7="Finalizado", IF(I7="EM VIAGEM","CARREGADO - COM SMP", IF(I7="Pré-SMP","CARREGADO - PRÉ-SMP", "CARREGADO - SEM SMP")), IF(I7="EM VIAGEM","ATRASADO CARREGAMENTO - COM SMP", IF(I7="Pré-SMP","ATRASADO CARREGAMENTO - PRÉ-SMP", "ATRASADO CARREGAMENTO - SEM SMP"))), IF(L7-NOW()<=1, "ATENCAO - PROXIMO", "OK - NO PRAZO" ))))))))))))),"") -> EM VIAGEM | E7: =IFERROR( IF( _xlfn.XLOOKUP( B7, 'LOCALIZAÇÃO DE CARGA'!$A$2:$A$702, 'LOCALIZAÇÃO DE CARGA'!$D$2:$D$702 )="", "", _xlfn.XLOOKUP( B7, 'LOCALIZAÇÃO DE CARGA'!$A$2:$A$702, 'LOCALIZAÇÃO DE CARGA'!$D$2:$D$702 ) ), "" ) -> Atrasado | F7: =IFERROR( IF( _xlfn.XLOOKUP( B7, 'LOCALIZAÇÃO DE CARGA'!$A$2:$A$702, 'LOCALIZAÇÃO DE CARGA'!$H$2:$H$702 )="", "", _xlfn.XLOOKUP( B7, 'LOCALIZAÇÃO DE CARGA'!$A$2:$A$702, 'LOCALIZAÇÃO DE CARGA'!$H$2:$H$702 ) ), "" ) -> MINAS SUL | G7: =IFERROR( IF( _xlfn.XLOOKUP( B7, 'LOCALIZAÇÃO DE CARGA'!$A$2:$A$702, 'LOCALIZAÇÃO DE CARGA'!$I$2:$I$702 )="", "", _xlfn.XLOOKUP( B7, 'LOCALIZAÇÃO DE CARGA'!$A$2:$A$702, 'LOCALIZAÇÃO DE CARGA'!$I$2:$I$702 ) ), "" ) -> LGCAJ | H7: =IFERROR( IF( _xlfn.XLOOKUP( B7, 'LOCALIZAÇÃO DE CARGA'!$A$2:$A$702, 'LOCALIZAÇÃO DE CARGA'!$F$2:$F$702 )="", "", _xlfn.XLOOKUP( B7, 'LOCALIZAÇÃO DE CARGA'!$A$2:$A$702, 'LOCALIZAÇÃO DE CARGA'!$F$2:$F$702 ) ), "" ) -> Andamento | I7: {=IFERROR( IF( INDEX( 'VISÃO LOGISTICA'!$C$2:$C$525, MATCH( TRUE, ISNUMBER(FIND(B7,'VISÃO LOGISTICA'!$A$2:$A$525)), 0 ) )="Em espera", "", INDEX( 'VISÃO LOGISTICA'!$C$2:$C$525, MATCH( TRUE, ISNUMBER(FIND(B7,'VISÃO LOGISTICA'!$A$2:$A$525)), 0 ) ) ), "" )} -> Em Viagem | J7: {=IFERROR( IF( OR( INDEX( 'VISÃO LOGISTICA'!$C$2:$C$2000, MATCH( TRUE, ISNUMBER(FIND(B7,'VISÃO LOGISTICA'!$A$2:$A$2000)), 0 ) )="Em espera", INDEX( 'VISÃO LOGISTICA'!$C$2:$C$2000, MATCH( TRUE, ISNUMBER(FIND(B7,'VISÃO LOGISTICA'!$A$2:$A$2000)), 0 ) )="" ), "", INDEX( 'VISÃO LOGISTICA'!$D$2:$D$2000, MATCH( TRUE, ISNUMBER(FIND(B7,'VISÃO LOGISTICA'!$A$2:$A$2000)), 0 ) ) ), "" )} -> DBM2B52 | K7: =IFERROR( IF( _xlfn.XLOOKUP( B7, 'LOCALIZAÇÃO DE CARGA'!$A$2:$A$702, 'LOCALIZAÇÃO DE CARGA'!$E$2:$E$702)="", "", _xlfn.XLOOKUP( B7, 'LOCALIZAÇÃO DE CARGA'!$A$2:$A$702, 'LOCALIZAÇÃO DE CARGA'!$E$2:$E$702) ), "" ) -> 1307797 | L7: {=IFERROR( _xlfn.LET( _xlpm.res,_xlfn.XLOOKUP(B7,'LOCALIZAÇÃO DE CARGA'!$A$2:$A$2000,'LOCALIZAÇÃO DE CARGA'!$G$2:$G$2000), IF(_xlpm.res="","",_xlpm.res) ), "" )} -> 46160.174 | M7: {=IFERROR( _xlfn.LET( _xlpm.load,_xlfn.XLOOKUP(B7,'LOCALIZAÇÃO DE CARGA'!$A$2:$A$2000,'LOCALIZAÇÃO DE CARGA'!$A$2:$A$2000), _xlpm.res,_xlfn.XLOOKUP(_xlpm.load,DOCUMENTOS!$A$2:$A$2000,DOCUMENTOS!$D$2:$D$2000), IF(_xlpm.res="","",_xlpm.res) ), "" )} -> 46157.875 | N7: =IFERROR(IF(M7="","",M7-TIME(1,0,0)),"") -> 46157.833 | O7: {=IFERROR( _xlfn.LET( _xlpm.res,_xlfn.XLOOKUP(B7,'LOCALIZAÇÃO DE CARGA'!$A$2:$A$2000,'LOCALIZAÇÃO DE CARGA'!$S$2:$S$2000), IF(_xlpm.res="","",_xlpm.res) ), "" )} -> 46161.292 | P7: {=IFERROR( _xlfn.LET( _xlpm.res,_xlfn.XLOOKUP(B7,'LOCALIZAÇÃO DE CARGA'!$A$2:$A$702,'LOCALIZAÇÃO DE CARGA'!$T$2:$T$702), IF(_xlpm.res="","",_xlpm.res) ), "" )} -> 46158.698 | Q7: =IFERROR( IF( _xlfn.XLOOKUP( B7, 'LOCALIZAÇÃO DE CARGA'!$A$2:$A$702, 'LOCALIZAÇÃO DE CARGA'!$K$2:$K$702 )="", "", _xlfn.XLOOKUP( B7, 'LOCALIZAÇÃO DE CARGA'!$A$2:$A$702, 'LOCALIZAÇÃO DE CARGA'!$K$2:$K$702 ) ), "" ) -> FUJIOKA ELETRO IMAGEM S/A - 74675690 | R7: =IF(Q7="","",TRIM(IFERROR(LEFT(LEFT(Q7,FIND(" - ",Q7)-1),FIND("(",LEFT(Q7,FIND(" - ",Q7)-1))-1),LEFT(Q7,FIND(" - ",Q7)-1)))) -> FUJIOKA ELETRO IMAGEM S/A | S7: {=IF(B7="","",IFERROR( INDEX( 'VISÃO LOGISTICA'!$L$2:$L$525, MATCH( TRUE, ISNUMBER(FIND(B7,'VISÃO LOGISTICA'!$A$2:$A$525)), 0 ) ), "" ))} -> AV CORONEL JOSE TEOFILO, UBERLANDIA/MG/BRASIL (0,19 Km) | T7: =IFERROR( _xlfn.LET( _xlpm.res,_xlfn.XLOOKUP(B7,'LOCALIZAÇÃO DE CARGA'!$A$2:$A$702,'LOCALIZAÇÃO DE CARGA'!$R$2:$R$702), IF(_xlpm.res="","",_xlpm.res) ), "" ) -> GOIANIA/GO/BRASIL
A8: =IF(M8="","",INT(M8)) -> 46160 | B8: 6021677 | C8: =IFERROR( IF(B8="","", IF(I8="Encerrada", "VERIFICAR SMP EM ANDAMENTO", IF(VALUE(SUBSTITUTE(K8,".",""))<100000, "DESCONSIDERA, VALOR NÃO RASTREADO", IF(AND(I8="EM VIAGEM",ISNUMBER(FIND("CAJAMAR/SP",S8))), IF(E8="Patio", "NA PENSKE - COM SMP - AGUARDANDO CARREGAMENTO", "NA PENSKE - COM SMP - AGUARDANDO SAÍDA"), IF(AND(I8="Pré-SMP",ISNUMBER(FIND("CAJAMAR/SP",S8))), IF(E8="Patio", "NA PENSKE - PRÉ-SMP - AGUARDANDO CARREGAMENTO", "NA PENSKE - PRÉ-SMP - AGUARDANDO SAÍDA"), IF(AND(I8="EM VIAGEM",ISNUMBER(FIND("ITAPOA/SC",S8))), "NA CLIF - COM SMP - AGUARDANDO SAÍDA", IF(AND(I8="Pré-SMP",ISNUMBER(FIND("ITAPOA/SC",S8))), "NA CLIF - PRÉ-SMP - AGUARDANDO SAÍDA", IF(I8="EM VIAGEM", "EM VIAGEM", IF(OR(L8="",N8=""), IF(I8="EM VIAGEM","SEM PREVISAO - COM SMP", IF(I8="Pré-SMP","SEM PREVISAO - PRÉ-SMP", "SEM PREVISAO - SEM SMP")), IF(M8>L8, IF(NOW()>N8, IF(E8="Finalizado", IF(I8="EM VIAGEM","CARREGADO - COM SMP", IF(I8="Pré-SMP","CARREGADO - PRÉ-SMP", "CARREGADO - SEM SMP")), IF(I8="EM VIAGEM","ATRASADO CARREGAMENTO - COM SMP - VERIFICAR AGENDAMENTO", IF(I8="Pré-SMP","ATRASADO CARREGAMENTO - PRÉ-SMP - VERIFICAR AGENDAMENTO", "ATRASADO CARREGAMENTO - SEM SMP - VERIFICAR AGENDAMENTO"))), IF(NOW()>L8, IF(I8="EM VIAGEM","ATRASADO ENTREGA - COM SMP - VERIFICAR AGENDAMENTO", IF(I8="Pré-SMP","ATRASADO ENTREGA - PRÉ-SMP - VERIFICAR AGENDAMENTO", "ATRASADO ENTREGA - SEM SMP - VERIFICAR AGENDAMENTO")), "OK NO PRAZO - VERIFICAR AGENDAMENTO")), IF(NOW()>L8, IF(I8="EM VIAGEM","ATRASADO ENTREGA - COM SMP", IF(I8="Pré-SMP","ATRASADO ENTREGA - PRÉ-SMP", "ATRASADO ENTREGA - SEM SMP")), IF(NOW()>N8, IF(E8="Finalizado", IF(I8="EM VIAGEM","CARREGADO - COM SMP", IF(I8="Pré-SMP","CARREGADO - PRÉ-SMP", "CARREGADO - SEM SMP")), IF(I8="EM VIAGEM","ATRASADO CARREGAMENTO - COM SMP", IF(I8="Pré-SMP","ATRASADO CARREGAMENTO - PRÉ-SMP", "ATRASADO CARREGAMENTO - SEM SMP"))), IF(L8-NOW()<=1, "ATENCAO - PROXIMO", "OK - NO PRAZO" ))))))))))))),"") -> OK - NO PRAZO | E8: =IFERROR( IF( _xlfn.XLOOKUP( B8, 'LOCALIZAÇÃO DE CARGA'!$A$2:$A$702, 'LOCALIZAÇÃO DE CARGA'!$D$2:$D$702 )="", "", _xlfn.XLOOKUP( B8, 'LOCALIZAÇÃO DE CARGA'!$A$2:$A$702, 'LOCALIZAÇÃO DE CARGA'!$D$2:$D$702 ) ), "" ) | F8: =IFERROR( IF( _xlfn.XLOOKUP( B8, 'LOCALIZAÇÃO DE CARGA'!$A$2:$A$702, 'LOCALIZAÇÃO DE CARGA'!$H$2:$H$702 )="", "", _xlfn.XLOOKUP( B8, 'LOCALIZAÇÃO DE CARGA'!$A$2:$A$702, 'LOCALIZAÇÃO DE CARGA'!$H$2:$H$702 ) ), "" ) -> LTA SOLUCOES | G8: =IFERROR( IF( _xlfn.XLOOKUP( B8, 'LOCALIZAÇÃO DE CARGA'!$A$2:$A$702, 'LOCALIZAÇÃO DE CARGA'!$I$2:$I$702 )="", "", _xlfn.XLOOKUP( B8, 'LOCALIZAÇÃO DE CARGA'!$A$2:$A$702, 'LOCALIZAÇÃO DE CARGA'!$I$2:$I$702 ) ), "" ) -> LGCAJ | H8: =IFERROR( IF( _xlfn.XLOOKUP( B8, 'LOCALIZAÇÃO DE CARGA'!$A$2:$A$702, 'LOCALIZAÇÃO DE CARGA'!$F$2:$F$702 )="", "", _xlfn.XLOOKUP( B8, 'LOCALIZAÇÃO DE CARGA'!$A$2:$A$702, 'LOCALIZAÇÃO DE CARGA'!$F$2:$F$702 ) ), "" ) -> Não iniciado | I8: {=IFERROR( IF( INDEX( 'VISÃO LOGISTICA'!$C$2:$C$525, MATCH( TRUE, ISNUMBER(FIND(B8,'VISÃO LOGISTICA'!$A$2:$A$525)), 0 ) )="Em espera", "", INDEX( 'VISÃO LOGISTICA'!$C$2:$C$525, MATCH( TRUE, ISNUMBER(FIND(B8,'VISÃO LOGISTICA'!$A$2:$A$525)), 0 ) ) ), "" )} | J8: {=IFERROR( IF( OR( INDEX( 'VISÃO LOGISTICA'!$C$2:$C$2000, MATCH( TRUE, ISNUMBER(FIND(B8,'VISÃO LOGISTICA'!$A$2:$A$2000)), 0 ) )="Em espera", INDEX( 'VISÃO LOGISTICA'!$C$2:$C$2000, MATCH( TRUE, ISNUMBER(FIND(B8,'VISÃO LOGISTICA'!$A$2:$A$2000)), 0 ) )="" ), "", INDEX( 'VISÃO LOGISTICA'!$D$2:$D$2000, MATCH( TRUE, ISNUMBER(FIND(B8,'VISÃO LOGISTICA'!$A$2:$A$2000)), 0 ) ) ), "" )} | K8: =IFERROR( IF( _xlfn.XLOOKUP( B8, 'LOCALIZAÇÃO DE CARGA'!$A$2:$A$702, 'LOCALIZAÇÃO DE CARGA'!$E$2:$E$702)="", "", _xlfn.XLOOKUP( B8, 'LOCALIZAÇÃO DE CARGA'!$A$2:$A$702, 'LOCALIZAÇÃO DE CARGA'!$E$2:$E$702) ), "" ) -> 1296572.4 | L8: {=IFERROR( _xlfn.LET( _xlpm.res,_xlfn.XLOOKUP(B8,'LOCALIZAÇÃO DE CARGA'!$A$2:$A$2000,'LOCALIZAÇÃO DE CARGA'!$G$2:$G$2000), IF(_xlpm.res="","",_xlpm.res) ), "" )} -> 46160.783 | M8: {=IFERROR( _xlfn.LET( _xlpm.load,_xlfn.XLOOKUP(B8,'LOCALIZAÇÃO DE CARGA'!$A$2:$A$2000,'LOCALIZAÇÃO DE CARGA'!$A$2:$A$2000), _xlpm.res,_xlfn.XLOOKUP(_xlpm.load,DOCUMENTOS!$A$2:$A$2000,DOCUMENTOS!$D$2:$D$2000), IF(_xlpm.res="","",_xlpm.res) ), "" )} -> 46160.375 | N8: =IFERROR(IF(M8="","",M8-TIME(1,0,0)),"") -> 46160.333 | O8: {=IFERROR( _xlfn.LET( _xlpm.res,_xlfn.XLOOKUP(B8,'LOCALIZAÇÃO DE CARGA'!$A$2:$A$2000,'LOCALIZAÇÃO DE CARGA'!$S$2:$S$2000), IF(_xlpm.res="","",_xlpm.res) ), "" )} -> 46161.25 | P8: {=IFERROR( _xlfn.LET( _xlpm.res,_xlfn.XLOOKUP(B8,'LOCALIZAÇÃO DE CARGA'!$A$2:$A$702,'LOCALIZAÇÃO DE CARGA'!$T$2:$T$702), IF(_xlpm.res="","",_xlpm.res) ), "" )} | Q8: =IFERROR( IF( _xlfn.XLOOKUP( B8, 'LOCALIZAÇÃO DE CARGA'!$A$2:$A$702, 'LOCALIZAÇÃO DE CARGA'!$K$2:$K$702 )="", "", _xlfn.XLOOKUP( B8, 'LOCALIZAÇÃO DE CARGA'!$A$2:$A$702, 'LOCALIZAÇÃO DE CARGA'!$K$2:$K$702 ) ), "" ) -> GRUPO CASAS BAHIA S.A(CD1401) - 25255030 | R8: =IF(Q8="","",TRIM(IFERROR(LEFT(LEFT(Q8,FIND(" - ",Q8)-1),FIND("(",LEFT(Q8,FIND(" - ",Q8)-1))-1),LEFT(Q8,FIND(" - ",Q8)-1)))) -> GRUPO CASAS BAHIA S.A | S8: {=IF(B8="","",IFERROR( INDEX( 'VISÃO LOGISTICA'!$L$2:$L$525, MATCH( TRUE, ISNUMBER(FIND(B8,'VISÃO LOGISTICA'!$A$2:$A$525)), 0 ) ), "" ))} | T8: =IFERROR( _xlfn.LET( _xlpm.res,_xlfn.XLOOKUP(B8,'LOCALIZAÇÃO DE CARGA'!$A$2:$A$702,'LOCALIZAÇÃO DE CARGA'!$R$2:$R$702), IF(_xlpm.res="","",_xlpm.res) ), "" ) -> DUQUE DE CAXIAS/RJ/BRASIL
A9: =IF(M9="","",INT(M9)) -> 46160 | B9: 6021733 | C9: =IFERROR( IF(B9="","", IF(I9="Encerrada", "VERIFICAR SMP EM ANDAMENTO", IF(VALUE(SUBSTITUTE(K9,".",""))<100000, "DESCONSIDERA, VALOR NÃO RASTREADO", IF(AND(I9="EM VIAGEM",ISNUMBER(FIND("CAJAMAR/SP",S9))), IF(E9="Patio", "NA PENSKE - COM SMP - AGUARDANDO CARREGAMENTO", "NA PENSKE - COM SMP - AGUARDANDO SAÍDA"), IF(AND(I9="Pré-SMP",ISNUMBER(FIND("CAJAMAR/SP",S9))), IF(E9="Patio", "NA PENSKE - PRÉ-SMP - AGUARDANDO CARREGAMENTO", "NA PENSKE - PRÉ-SMP - AGUARDANDO SAÍDA"), IF(AND(I9="EM VIAGEM",ISNUMBER(FIND("ITAPOA/SC",S9))), "NA CLIF - COM SMP - AGUARDANDO SAÍDA", IF(AND(I9="Pré-SMP",ISNUMBER(FIND("ITAPOA/SC",S9))), "NA CLIF - PRÉ-SMP - AGUARDANDO SAÍDA", IF(I9="EM VIAGEM", "EM VIAGEM", IF(OR(L9="",N9=""), IF(I9="EM VIAGEM","SEM PREVISAO - COM SMP", IF(I9="Pré-SMP","SEM PREVISAO - PRÉ-SMP", "SEM PREVISAO - SEM SMP")), IF(M9>L9, IF(NOW()>N9, IF(E9="Finalizado", IF(I9="EM VIAGEM","CARREGADO - COM SMP", IF(I9="Pré-SMP","CARREGADO - PRÉ-SMP", "CARREGADO - SEM SMP")), IF(I9="EM VIAGEM","ATRASADO CARREGAMENTO - COM SMP - VERIFICAR AGENDAMENTO", IF(I9="Pré-SMP","ATRASADO CARREGAMENTO - PRÉ-SMP - VERIFICAR AGENDAMENTO", "ATRASADO CARREGAMENTO - SEM SMP - VERIFICAR AGENDAMENTO"))), IF(NOW()>L9, IF(I9="EM VIAGEM","ATRASADO ENTREGA - COM SMP - VERIFICAR AGENDAMENTO", IF(I9="Pré-SMP","ATRASADO ENTREGA - PRÉ-SMP - VERIFICAR AGENDAMENTO", "ATRASADO ENTREGA - SEM SMP - VERIFICAR AGENDAMENTO")), "OK NO PRAZO - VERIFICAR AGENDAMENTO")), IF(NOW()>L9, IF(I9="EM VIAGEM","ATRASADO ENTREGA - COM SMP", IF(I9="Pré-SMP","ATRASADO ENTREGA - PRÉ-SMP", "ATRASADO ENTREGA - SEM SMP")), IF(NOW()>N9, IF(E9="Finalizado", IF(I9="EM VIAGEM","CARREGADO - COM SMP", IF(I9="Pré-SMP","CARREGADO - PRÉ-SMP", "CARREGADO - SEM SMP")), IF(I9="EM VIAGEM","ATRASADO CARREGAMENTO - COM SMP", IF(I9="Pré-SMP","ATRASADO CARREGAMENTO - PRÉ-SMP", "ATRASADO CARREGAMENTO - SEM SMP"))), IF(L9-NOW()<=1, "ATENCAO - PROXIMO", "OK - NO PRAZO" ))))))))))))),"") -> OK - NO PRAZO | E9: =IFERROR( IF( _xlfn.XLOOKUP( B9, 'LOCALIZAÇÃO DE CARGA'!$A$2:$A$702, 'LOCALIZAÇÃO DE CARGA'!$D$2:$D$702 )="", "", _xlfn.XLOOKUP( B9, 'LOCALIZAÇÃO DE CARGA'!$A$2:$A$702, 'LOCALIZAÇÃO DE CARGA'!$D$2:$D$702 ) ), "" ) | F9: =IFERROR( IF( _xlfn.XLOOKUP( B9, 'LOCALIZAÇÃO DE CARGA'!$A$2:$A$702, 'LOCALIZAÇÃO DE CARGA'!$H$2:$H$702 )="", "", _xlfn.XLOOKUP( B9, 'LOCALIZAÇÃO DE CARGA'!$A$2:$A$702, 'LOCALIZAÇÃO DE CARGA'!$H$2:$H$702 ) ), "" ) -> CABRAL & CAB | G9: =IFERROR( IF( _xlfn.XLOOKUP( B9, 'LOCALIZAÇÃO DE CARGA'!$A$2:$A$702, 'LOCALIZAÇÃO DE CARGA'!$I$2:$I$702 )="", "", _xlfn.XLOOKUP( B9, 'LOCALIZAÇÃO DE CARGA'!$A$2:$A$702, 'LOCALIZAÇÃO DE CARGA'!$I$2:$I$702 ) ), "" ) -> LGREC | H9: =IFERROR( IF( _xlfn.XLOOKUP( B9, 'LOCALIZAÇÃO DE CARGA'!$A$2:$A$702, 'LOCALIZAÇÃO DE CARGA'!$F$2:$F$702 )="", "", _xlfn.XLOOKUP( B9, 'LOCALIZAÇÃO DE CARGA'!$A$2:$A$702, 'LOCALIZAÇÃO DE CARGA'!$F$2:$F$702 ) ), "" ) -> Não iniciado | I9: {=IFERROR( IF( INDEX( 'VISÃO LOGISTICA'!$C$2:$C$525, MATCH( TRUE, ISNUMBER(FIND(B9,'VISÃO LOGISTICA'!$A$2:$A$525)), 0 ) )="Em espera", "", INDEX( 'VISÃO LOGISTICA'!$C$2:$C$525, MATCH( TRUE, ISNUMBER(FIND(B9,'VISÃO LOGISTICA'!$A$2:$A$525)), 0 ) ) ), "" )} | J9: {=IFERROR( IF( OR( INDEX( 'VISÃO LOGISTICA'!$C$2:$C$2000, MATCH( TRUE, ISNUMBER(FIND(B9,'VISÃO LOGISTICA'!$A$2:$A$2000)), 0 ) )="Em espera", INDEX( 'VISÃO LOGISTICA'!$C$2:$C$2000, MATCH( TRUE, ISNUMBER(FIND(B9,'VISÃO LOGISTICA'!$A$2:$A$2000)), 0 ) )="" ), "", INDEX( 'VISÃO LOGISTICA'!$D$2:$D$2000, MATCH( TRUE, ISNUMBER(FIND(B9,'VISÃO LOGISTICA'!$A$2:$A$2000)), 0 ) ) ), "" )} | K9: =IFERROR( IF( _xlfn.XLOOKUP( B9, 'LOCALIZAÇÃO DE CARGA'!$A$2:$A$702, 'LOCALIZAÇÃO DE CARGA'!$E$2:$E$702)="", "", _xlfn.XLOOKUP( B9, 'LOCALIZAÇÃO DE CARGA'!$A$2:$A$702, 'LOCALIZAÇÃO DE CARGA'!$E$2:$E$702) ), "" ) -> 1257605 | L9: {=IFERROR( _xlfn.LET( _xlpm.res,_xlfn.XLOOKUP(B9,'LOCALIZAÇÃO DE CARGA'!$A$2:$A$2000,'LOCALIZAÇÃO DE CARGA'!$G$2:$G$2000), IF(_xlpm.res="","",_xlpm.res) ), "" )} -> 46160.854 | M9: {=IFERROR( _xlfn.LET( _xlpm.load,_xlfn.XLOOKUP(B9,'LOCALIZAÇÃO DE CARGA'!$A$2:$A$2000,'LOCALIZAÇÃO DE CARGA'!$A$2:$A$2000), _xlpm.res,_xlfn.XLOOKUP(_xlpm.load,DOCUMENTOS!$A$2:$A$2000,DOCUMENTOS!$D$2:$D$2000), IF(_xlpm.res="","",_xlpm.res) ), "" )} -> 46160.854 | N9: =IFERROR(IF(M9="","",M9-TIME(1,0,0)),"") -> 46160.812 | O9: {=IFERROR( _xlfn.LET( _xlpm.res,_xlfn.XLOOKUP(B9,'LOCALIZAÇÃO DE CARGA'!$A$2:$A$2000,'LOCALIZAÇÃO DE CARGA'!$S$2:$S$2000), IF(_xlpm.res="","",_xlpm.res) ), "" )} -> 46162.25 | P9: {=IFERROR( _xlfn.LET( _xlpm.res,_xlfn.XLOOKUP(B9,'LOCALIZAÇÃO DE CARGA'!$A$2:$A$702,'LOCALIZAÇÃO DE CARGA'!$T$2:$T$702), IF(_xlpm.res="","",_xlpm.res) ), "" )} | Q9: =IFERROR( IF( _xlfn.XLOOKUP( B9, 'LOCALIZAÇÃO DE CARGA'!$A$2:$A$702, 'LOCALIZAÇÃO DE CARGA'!$K$2:$K$702 )="", "", _xlfn.XLOOKUP( B9, 'LOCALIZAÇÃO DE CARGA'!$A$2:$A$702, 'LOCALIZAÇÃO DE CARGA'!$K$2:$K$702 ) ), "" ) -> GRUPO CASAS BAHIA S.A(CD1400) - 42816270 | R9: =IF(Q9="","",TRIM(IFERROR(LEFT(LEFT(Q9,FIND(" - ",Q9)-1),FIND("(",LEFT(Q9,FIND(" - ",Q9)-1))-1),LEFT(Q9,FIND(" - ",Q9)-1)))) -> GRUPO CASAS BAHIA S.A | S9: {=IF(B9="","",IFERROR( INDEX( 'VISÃO LOGISTICA'!$L$2:$L$525, MATCH( TRUE, ISNUMBER(FIND(B9,'VISÃO LOGISTICA'!$A$2:$A$525)), 0 ) ), "" ))} | T9: =IFERROR( _xlfn.LET( _xlpm.res,_xlfn.XLOOKUP(B9,'LOCALIZAÇÃO DE CARGA'!$A$2:$A$702,'LOCALIZAÇÃO DE CARGA'!$R$2:$R$702), IF(_xlpm.res="","",_xlpm.res) ), "" ) -> CAMACARI/BA/BRASIL
A10: =IF(M10="","",INT(M10)) -> 46160 | B10: 6021734 | C10: =IFERROR( IF(B10="","", IF(I10="Encerrada", "VERIFICAR SMP EM ANDAMENTO", IF(VALUE(SUBSTITUTE(K10,".",""))<100000, "DESCONSIDERA, VALOR NÃO RASTREADO", IF(AND(I10="EM VIAGEM",ISNUMBER(FIND("CAJAMAR/SP",S10))), IF(E10="Patio", "NA PENSKE - COM SMP - AGUARDANDO CARREGAMENTO", "NA PENSKE - COM SMP - AGUARDANDO SAÍDA"), IF(AND(I10="Pré-SMP",ISNUMBER(FIND("CAJAMAR/SP",S10))), IF(E10="Patio", "NA PENSKE - PRÉ-SMP - AGUARDANDO CARREGAMENTO", "NA PENSKE - PRÉ-SMP - AGUARDANDO SAÍDA"), IF(AND(I10="EM VIAGEM",ISNUMBER(FIND("ITAPOA/SC",S10))), "NA CLIF - COM SMP - AGUARDANDO SAÍDA", IF(AND(I10="Pré-SMP",ISNUMBER(FIND("ITAPOA/SC",S10))), "NA CLIF - PRÉ-SMP - AGUARDANDO SAÍDA", IF(I10="EM VIAGEM", "EM VIAGEM", IF(OR(L10="",N10=""), IF(I10="EM VIAGEM","SEM PREVISAO - COM SMP", IF(I10="Pré-SMP","SEM PREVISAO - PRÉ-SMP", "SEM PREVISAO - SEM SMP")), IF(M10>L10, IF(NOW()>N10, IF(E10="Finalizado", IF(I10="EM VIAGEM","CARREGADO - COM SMP", IF(I10="Pré-SMP","CARREGADO - PRÉ-SMP", "CARREGADO - SEM SMP")), IF(I10="EM VIAGEM","ATRASADO CARREGAMENTO - COM SMP - VERIFICAR AGENDAMENTO", IF(I10="Pré-SMP","ATRASADO CARREGAMENTO - PRÉ-SMP - VERIFICAR AGENDAMENTO", "ATRASADO CARREGAMENTO - SEM SMP - VERIFICAR AGENDAMENTO"))), IF(NOW()>L10, IF(I10="EM VIAGEM","ATRASADO ENTREGA - COM SMP - VERIFICAR AGENDAMENTO", IF(I10="Pré-SMP","ATRASADO ENTREGA - PRÉ-SMP - VERIFICAR AGENDAMENTO", "ATRASADO ENTREGA - SEM SMP - VERIFICAR AGENDAMENTO")), "OK NO PRAZO - VERIFICAR AGENDAMENTO")), IF(NOW()>L10, IF(I10="EM VIAGEM","ATRASADO ENTREGA - COM SMP", IF(I10="Pré-SMP","ATRASADO ENTREGA - PRÉ-SMP", "ATRASADO ENTREGA - SEM SMP")), IF(NOW()>N10, IF(E10="Finalizado", IF(I10="EM VIAGEM","CARREGADO - COM SMP", IF(I10="Pré-SMP","CARREGADO - PRÉ-SMP", "CARREGADO - SEM SMP")), IF(I10="EM VIAGEM","ATRASADO CARREGAMENTO - COM SMP", IF(I10="Pré-SMP","ATRASADO CARREGAMENTO - PRÉ-SMP", "ATRASADO CARREGAMENTO - SEM SMP"))), IF(L10-NOW()<=1, "ATENCAO - PROXIMO", "OK - NO PRAZO" ))))))))))))),"") -> OK - NO PRAZO | E10: =IFERROR( IF( _xlfn.XLOOKUP( B10, 'LOCALIZAÇÃO DE CARGA'!$A$2:$A$702, 'LOCALIZAÇÃO DE CARGA'!$D$2:$D$702 )="", "", _xlfn.XLOOKUP( B10, 'LOCALIZAÇÃO DE CARGA'!$A$2:$A$702, 'LOCALIZAÇÃO DE CARGA'!$D$2:$D$702 ) ), "" ) | F10: =IFERROR( IF( _xlfn.XLOOKUP( B10, 'LOCALIZAÇÃO DE CARGA'!$A$2:$A$702, 'LOCALIZAÇÃO DE CARGA'!$H$2:$H$702 )="", "", _xlfn.XLOOKUP( B10, 'LOCALIZAÇÃO DE CARGA'!$A$2:$A$702, 'LOCALIZAÇÃO DE CARGA'!$H$2:$H$702 ) ), "" ) -> RODOPENHA | G10: =IFERROR( IF( _xlfn.XLOOKUP( B10, 'LOCALIZAÇÃO DE CARGA'!$A$2:$A$702, 'LOCALIZAÇÃO DE CARGA'!$I$2:$I$702 )="", "", _xlfn.XLOOKUP( B10, 'LOCALIZAÇÃO DE CARGA'!$A$2:$A$702, 'LOCALIZAÇÃO DE CARGA'!$I$2:$I$702 ) ), "" ) -> LGREC | H10: =IFERROR( IF( _xlfn.XLOOKUP( B10, 'LOCALIZAÇÃO DE CARGA'!$A$2:$A$702, 'LOCALIZAÇÃO DE CARGA'!$F$2:$F$702 )="", "", _xlfn.XLOOKUP( B10, 'LOCALIZAÇÃO DE CARGA'!$A$2:$A$702, 'LOCALIZAÇÃO DE CARGA'!$F$2:$F$702 ) ), "" ) -> Não iniciado | I10: {=IFERROR( IF( INDEX( 'VISÃO LOGISTICA'!$C$2:$C$525, MATCH( TRUE, ISNUMBER(FIND(B10,'VISÃO LOGISTICA'!$A$2:$A$525)), 0 ) )="Em espera", "", INDEX( 'VISÃO LOGISTICA'!$C$2:$C$525, MATCH( TRUE, ISNUMBER(FIND(B10,'VISÃO LOGISTICA'!$A$2:$A$525)), 0 ) ) ), "" )} | J10: {=IFERROR( IF( OR( INDEX( 'VISÃO LOGISTICA'!$C$2:$C$2000, MATCH( TRUE, ISNUMBER(FIND(B10,'VISÃO LOGISTICA'!$A$2:$A$2000)), 0 ) )="Em espera", INDEX( 'VISÃO LOGISTICA'!$C$2:$C$2000, MATCH( TRUE, ISNUMBER(FIND(B10,'VISÃO LOGISTICA'!$A$2:$A$2000)), 0 ) )="" ), "", INDEX( 'VISÃO LOGISTICA'!$D$2:$D$2000, MATCH( TRUE, ISNUMBER(FIND(B10,'VISÃO LOGISTICA'!$A$2:$A$2000)), 0 ) ) ), "" )} | K10: =IFERROR( IF( _xlfn.XLOOKUP( B10, 'LOCALIZAÇÃO DE CARGA'!$A$2:$A$702, 'LOCALIZAÇÃO DE CARGA'!$E$2:$E$702)="", "", _xlfn.XLOOKUP( B10, 'LOCALIZAÇÃO DE CARGA'!$A$2:$A$702, 'LOCALIZAÇÃO DE CARGA'!$E$2:$E$702) ), "" ) -> 1197980.5 | L10: {=IFERROR( _xlfn.LET( _xlpm.res,_xlfn.XLOOKUP(B10,'LOCALIZAÇÃO DE CARGA'!$A$2:$A$2000,'LOCALIZAÇÃO DE CARGA'!$G$2:$G$2000), IF(_xlpm.res="","",_xlpm.res) ), "" )} -> 46160.854 | M10: {=IFERROR( _xlfn.LET( _xlpm.load,_xlfn.XLOOKUP(B10,'LOCALIZAÇÃO DE CARGA'!$A$2:$A$2000,'LOCALIZAÇÃO DE CARGA'!$A$2:$A$2000), _xlpm.res,_xlfn.XLOOKUP(_xlpm.load,DOCUMENTOS!$A$2:$A$2000,DOCUMENTOS!$D$2:$D$2000), IF(_xlpm.res="","",_xlpm.res) ), "" )} -> 46160.854 | N10: =IFERROR(IF(M10="","",M10-TIME(1,0,0)),"") -> 46160.812 | O10: {=IFERROR( _xlfn.LET( _xlpm.res,_xlfn.XLOOKUP(B10,'LOCALIZAÇÃO DE CARGA'!$A$2:$A$2000,'LOCALIZAÇÃO DE CARGA'!$S$2:$S$2000), IF(_xlpm.res="","",_xlpm.res) ), "" )} -> 46162.25 | P10: {=IFERROR( _xlfn.LET( _xlpm.res,_xlfn.XLOOKUP(B10,'LOCALIZAÇÃO DE CARGA'!$A$2:$A$702,'LOCALIZAÇÃO DE CARGA'!$T$2:$T$702), IF(_xlpm.res="","",_xlpm.res) ), "" )} | Q10: =IFERROR( IF( _xlfn.XLOOKUP( B10, 'LOCALIZAÇÃO DE CARGA'!$A$2:$A$702, 'LOCALIZAÇÃO DE CARGA'!$K$2:$K$702 )="", "", _xlfn.XLOOKUP( B10, 'LOCALIZAÇÃO DE CARGA'!$A$2:$A$702, 'LOCALIZAÇÃO DE CARGA'!$K$2:$K$702 ) ), "" ) -> GRUPO CASAS BAHIA S.A(CD1400) - 42816270 | R10: =IF(Q10="","",TRIM(IFERROR(LEFT(LEFT(Q10,FIND(" - ",Q10)-1),FIND("(",LEFT(Q10,FIND(" - ",Q10)-1))-1),LEFT(Q10,FIND(" - ",Q10)-1)))) -> GRUPO CASAS BAHIA S.A | S10: {=IF(B10="","",IFERROR( INDEX( 'VISÃO LOGISTICA'!$L$2:$L$525, MATCH( TRUE, ISNUMBER(FIND(B10,'VISÃO LOGISTICA'!$A$2:$A$525)), 0 ) ), "" ))} | T10: =IFERROR( _xlfn.LET( _xlpm.res,_xlfn.XLOOKUP(B10,'LOCALIZAÇÃO DE CARGA'!$A$2:$A$702,'LOCALIZAÇÃO DE CARGA'!$R$2:$R$702), IF(_xlpm.res="","",_xlpm.res) ), "" ) -> CAMACARI/BA/BRASIL
A11: =IF(M11="","",INT(M11)) -> 46157 | B11: 6022337 | C11: =IFERROR( IF(B11="","", IF(I11="Encerrada", "VERIFICAR SMP EM ANDAMENTO", IF(VALUE(SUBSTITUTE(K11,".",""))<100000, "DESCONSIDERA, VALOR NÃO RASTREADO", IF(AND(I11="EM VIAGEM",ISNUMBER(FIND("CAJAMAR/SP",S11))), IF(E11="Patio", "NA PENSKE - COM SMP - AGUARDANDO CARREGAMENTO", "NA PENSKE - COM SMP - AGUARDANDO SAÍDA"), IF(AND(I11="Pré-SMP",ISNUMBER(FIND("CAJAMAR/SP",S11))), IF(E11="Patio", "NA PENSKE - PRÉ-SMP - AGUARDANDO CARREGAMENTO", "NA PENSKE - PRÉ-SMP - AGUARDANDO SAÍDA"), IF(AND(I11="EM VIAGEM",ISNUMBER(FIND("ITAPOA/SC",S11))), "NA CLIF - COM SMP - AGUARDANDO SAÍDA", IF(AND(I11="Pré-SMP",ISNUMBER(FIND("ITAPOA/SC",S11))), "NA CLIF - PRÉ-SMP - AGUARDANDO SAÍDA", IF(I11="EM VIAGEM", "EM VIAGEM", IF(OR(L11="",N11=""), IF(I11="EM VIAGEM","SEM PREVISAO - COM SMP", IF(I11="Pré-SMP","SEM PREVISAO - PRÉ-SMP", "SEM PREVISAO - SEM SMP")), IF(M11>L11, IF(NOW()>N11, IF(E11="Finalizado", IF(I11="EM VIAGEM","CARREGADO - COM SMP", IF(I11="Pré-SMP","CARREGADO - PRÉ-SMP", "CARREGADO - SEM SMP")), IF(I11="EM VIAGEM","ATRASADO CARREGAMENTO - COM SMP - VERIFICAR AGENDAMENTO", IF(I11="Pré-SMP","ATRASADO CARREGAMENTO - PRÉ-SMP - VERIFICAR AGENDAMENTO", "ATRASADO CARREGAMENTO - SEM SMP - VERIFICAR AGENDAMENTO"))), IF(NOW()>L11, IF(I11="EM VIAGEM","ATRASADO ENTREGA - COM SMP - VERIFICAR AGENDAMENTO", IF(I11="Pré-SMP","ATRASADO ENTREGA - PRÉ-SMP - VERIFICAR AGENDAMENTO", "ATRASADO ENTREGA - SEM SMP - VERIFICAR AGENDAMENTO")), "OK NO PRAZO - VERIFICAR AGENDAMENTO")), IF(NOW()>L11, IF(I11="EM VIAGEM","ATRASADO ENTREGA - COM SMP", IF(I11="Pré-SMP","ATRASADO ENTREGA - PRÉ-SMP", "ATRASADO ENTREGA - SEM SMP")), IF(NOW()>N11, IF(E11="Finalizado", IF(I11="EM VIAGEM","CARREGADO - COM SMP", IF(I11="Pré-SMP","CARREGADO - PRÉ-SMP", "CARREGADO - SEM SMP")), IF(I11="EM VIAGEM","ATRASADO CARREGAMENTO - COM SMP", IF(I11="Pré-SMP","ATRASADO CARREGAMENTO - PRÉ-SMP", "ATRASADO CARREGAMENTO - SEM SMP"))), IF(L11-NOW()<=1, "ATENCAO - PROXIMO", "OK - NO PRAZO" ))))))))))))),"") -> EM VIAGEM | E11: =IFERROR( IF( _xlfn.XLOOKUP( B11, 'LOCALIZAÇÃO DE CARGA'!$A$2:$A$702, 'LOCALIZAÇÃO DE CARGA'!$D$2:$D$702 )="", "", _xlfn.XLOOKUP( B11, 'LOCALIZAÇÃO DE CARGA'!$A$2:$A$702, 'LOCALIZAÇÃO DE CARGA'!$D$2:$D$702 ) ), "" ) -> Saida do WH | F11: =IFERROR( IF( _xlfn.XLOOKUP( B11, 'LOCALIZAÇÃO DE CARGA'!$A$2:$A$702, 'LOCALIZAÇÃO DE CARGA'!$H$2:$H$702 )="", "", _xlfn.XLOOKUP( B11, 'LOCALIZAÇÃO DE CARGA'!$A$2:$A$702, 'LOCALIZAÇÃO DE CARGA'!$H$2:$H$702 ) ), "" ) -> RODOBRAS TR | G11: =IFERROR( IF( _xlfn.XLOOKUP( B11, 'LOCALIZAÇÃO DE CARGA'!$A$2:$A$702, 'LOCALIZAÇÃO DE CARGA'!$I$2:$I$702 )="", "", _xlfn.XLOOKUP( B11, 'LOCALIZAÇÃO DE CARGA'!$A$2:$A$702, 'LOCALIZAÇÃO DE CARGA'!$I$2:$I$702 ) ), "" ) -> LGCAJ | H11: =IFERROR( IF( _xlfn.XLOOKUP( B11, 'LOCALIZAÇÃO DE CARGA'!$A$2:$A$702, 'LOCALIZAÇÃO DE CARGA'!$F$2:$F$702 )="", "", _xlfn.XLOOKUP( B11, 'LOCALIZAÇÃO DE CARGA'!$A$2:$A$702, 'LOCALIZAÇÃO DE CARGA'!$F$2:$F$702 ) ), "" ) -> Andamento | I11: {=IFERROR( IF( INDEX( 'VISÃO LOGISTICA'!$C$2:$C$525, MATCH( TRUE, ISNUMBER(FIND(B11,'VISÃO LOGISTICA'!$A$2:$A$525)), 0 ) )="Em espera", "", INDEX( 'VISÃO LOGISTICA'!$C$2:$C$525, MATCH( TRUE, ISNUMBER(FIND(B11,'VISÃO LOGISTICA'!$A$2:$A$525)), 0 ) ) ), "" )} -> Em Viagem | J11: {=IFERROR( IF( OR( INDEX( 'VISÃO LOGISTICA'!$C$2:$C$2000, MATCH( TRUE, ISNUMBER(FIND(B11,'VISÃO LOGISTICA'!$A$2:$A$2000)), 0 ) )="Em espera", INDEX( 'VISÃO LOGISTICA'!$C$2:$C$2000, MATCH( TRUE, ISNUMBER(FIND(B11,'VISÃO LOGISTICA'!$A$2:$A$2000)), 0 ) )="" ), "", INDEX( 'VISÃO LOGISTICA'!$D$2:$D$2000, MATCH( TRUE, ISNUMBER(FIND(B11,'VISÃO LOGISTICA'!$A$2:$A$2000)), 0 ) ) ), "" )} -> JBY4D00 | K11: =IFERROR( IF( _xlfn.XLOOKUP( B11, 'LOCALIZAÇÃO DE CARGA'!$A$2:$A$702, 'LOCALIZAÇÃO DE CARGA'!$E$2:$E$702)="", "", _xlfn.XLOOKUP( B11, 'LOCALIZAÇÃO DE CARGA'!$A$2:$A$702, 'LOCALIZAÇÃO DE CARGA'!$E$2:$E$702) ), "" ) -> 1140398 | L11: {=IFERROR( _xlfn.LET( _xlpm.res,_xlfn.XLOOKUP(B11,'LOCALIZAÇÃO DE CARGA'!$A$2:$A$2000,'LOCALIZAÇÃO DE CARGA'!$G$2:$G$2000), IF(_xlpm.res="","",_xlpm.res) ), "" )} -> 46159.99 | M11: {=IFERROR( _xlfn.LET( _xlpm.load,_xlfn.XLOOKUP(B11,'LOCALIZAÇÃO DE CARGA'!$A$2:$A$2000,'LOCALIZAÇÃO DE CARGA'!$A$2:$A$2000), _xlpm.res,_xlfn.XLOOKUP(_xlpm.load,DOCUMENTOS!$A$2:$A$2000,DOCUMENTOS!$D$2:$D$2000), IF(_xlpm.res="","",_xlpm.res) ), "" )} -> 46157.583 | N11: =IFERROR(IF(M11="","",M11-TIME(1,0,0)),"") -> 46157.542 | O11: {=IFERROR( _xlfn.LET( _xlpm.res,_xlfn.XLOOKUP(B11,'LOCALIZAÇÃO DE CARGA'!$A$2:$A$2000,'LOCALIZAÇÃO DE CARGA'!$S$2:$S$2000), IF(_xlpm.res="","",_xlpm.res) ), "" )} -> 46161.25 | P11: {=IFERROR( _xlfn.LET( _xlpm.res,_xlfn.XLOOKUP(B11,'LOCALIZAÇÃO DE CARGA'!$A$2:$A$702,'LOCALIZAÇÃO DE CARGA'!$T$2:$T$702), IF(_xlpm.res="","",_xlpm.res) ), "" )} -> 46159.027 | Q11: =IFERROR( IF( _xlfn.XLOOKUP( B11, 'LOCALIZAÇÃO DE CARGA'!$A$2:$A$702, 'LOCALIZAÇÃO DE CARGA'!$K$2:$K$702 )="", "", _xlfn.XLOOKUP( B11, 'LOCALIZAÇÃO DE CARGA'!$A$2:$A$702, 'LOCALIZAÇÃO DE CARGA'!$K$2:$K$702 ) ), "" ) -> CARREFOUR COMERCIO E INDUSTRIA LTDA - 91060410 | R11: =IF(Q11="","",TRIM(IFERROR(LEFT(LEFT(Q11,FIND(" - ",Q11)-1),FIND("(",LEFT(Q11,FIND(" - ",Q11)-1))-1),LEFT(Q11,FIND(" - ",Q11)-1)))) -> CARREFOUR COMERCIO E INDUSTRIA LTDA | S11: {=IF(B11="","",IFERROR( INDEX( 'VISÃO LOGISTICA'!$L$2:$L$525, MATCH( TRUE, ISNUMBER(FIND(B11,'VISÃO LOGISTICA'!$A$2:$A$525)), 0 ) ), "" ))} -> REPRESA, COTIA/SP/BRASIL (0,1 Km) | T11: =IFERROR( _xlfn.LET( _xlpm.res,_xlfn.XLOOKUP(B11,'LOCALIZAÇÃO DE CARGA'!$A$2:$A$702,'LOCALIZAÇÃO DE CARGA'!$R$2:$R$702), IF(_xlpm.res="","",_xlpm.res) ), "" ) -> PORTO ALEGRE/RS/BRASIL
A12: =IF(M12="","",INT(M12)) -> 46157 | B12: 6022057 | C12: =IFERROR( IF(B12="","", IF(I12="Encerrada", "VERIFICAR SMP EM ANDAMENTO", IF(VALUE(SUBSTITUTE(K12,".",""))<100000, "DESCONSIDERA, VALOR NÃO RASTREADO", IF(AND(I12="EM VIAGEM",ISNUMBER(FIND("CAJAMAR/SP",S12))), IF(E12="Patio", "NA PENSKE - COM SMP - AGUARDANDO CARREGAMENTO", "NA PENSKE - COM SMP - AGUARDANDO SAÍDA"), IF(AND(I12="Pré-SMP",ISNUMBER(FIND("CAJAMAR/SP",S12))), IF(E12="Patio", "NA PENSKE - PRÉ-SMP - AGUARDANDO CARREGAMENTO", "NA PENSKE - PRÉ-SMP - AGUARDANDO SAÍDA"), IF(AND(I12="EM VIAGEM",ISNUMBER(FIND("ITAPOA/SC",S12))), "NA CLIF - COM SMP - AGUARDANDO SAÍDA", IF(AND(I12="Pré-SMP",ISNUMBER(FIND("ITAPOA/SC",S12))), "NA CLIF - PRÉ-SMP - AGUARDANDO SAÍDA", IF(I12="EM VIAGEM", "EM VIAGEM", IF(OR(L12="",N12=""), IF(I12="EM VIAGEM","SEM PREVISAO - COM SMP", IF(I12="Pré-SMP","SEM PREVISAO - PRÉ-SMP", "SEM PREVISAO - SEM SMP")), IF(M12>L12, IF(NOW()>N12, IF(E12="Finalizado", IF(I12="EM VIAGEM","CARREGADO - COM SMP", IF(I12="Pré-SMP","CARREGADO - PRÉ-SMP", "CARREGADO - SEM SMP")), IF(I12="EM VIAGEM","ATRASADO CARREGAMENTO - COM SMP - VERIFICAR AGENDAMENTO", IF(I12="Pré-SMP","ATRASADO CARREGAMENTO - PRÉ-SMP - VERIFICAR AGENDAMENTO", "ATRASADO CARREGAMENTO - SEM SMP - VERIFICAR AGENDAMENTO"))), IF(NOW()>L12, IF(I12="EM VIAGEM","ATRASADO ENTREGA - COM SMP - VERIFICAR AGENDAMENTO", IF(I12="Pré-SMP","ATRASADO ENTREGA - PRÉ-SMP - VERIFICAR AGENDAMENTO", "ATRASADO ENTREGA - SEM SMP - VERIFICAR AGENDAMENTO")), "OK NO PRAZO - VERIFICAR AGENDAMENTO")), IF(NOW()>L12, IF(I12="EM VIAGEM","ATRASADO ENTREGA - COM SMP", IF(I12="Pré-SMP","ATRASADO ENTREGA - PRÉ-SMP", "ATRASADO ENTREGA - SEM SMP")), IF(NOW()>N12, IF(E12="Finalizado", IF(I12="EM VIAGEM","CARREGADO - COM SMP", IF(I12="Pré-SMP","CARREGADO - PRÉ-SMP", "CARREGADO - SEM SMP")), IF(I12="EM VIAGEM","ATRASADO CARREGAMENTO - COM SMP", IF(I12="Pré-SMP","ATRASADO CARREGAMENTO - PRÉ-SMP", "ATRASADO CARREGAMENTO - SEM SMP"))), IF(L12-NOW()<=1, "ATENCAO - PROXIMO", "OK - NO PRAZO" ))))))))))))),"") -> EM VIAGEM | E12: =IFERROR( IF( _xlfn.XLOOKUP( B12, 'LOCALIZAÇÃO DE CARGA'!$A$2:$A$702, 'LOCALIZAÇÃO DE CARGA'!$D$2:$D$702 )="", "", _xlfn.XLOOKUP( B12, 'LOCALIZAÇÃO DE CARGA'!$A$2:$A$702, 'LOCALIZAÇÃO DE CARGA'!$D$2:$D$702 ) ), "" ) -> Saida do WH | F12: =IFERROR( IF( _xlfn.XLOOKUP( B12, 'LOCALIZAÇÃO DE CARGA'!$A$2:$A$702, 'LOCALIZAÇÃO DE CARGA'!$H$2:$H$702 )="", "", _xlfn.XLOOKUP( B12, 'LOCALIZAÇÃO DE CARGA'!$A$2:$A$702, 'LOCALIZAÇÃO DE CARGA'!$H$2:$H$702 ) ), "" ) -> TR RAMTHUN | G12: =IFERROR( IF( _xlfn.XLOOKUP( B12, 'LOCALIZAÇÃO DE CARGA'!$A$2:$A$702, 'LOCALIZAÇÃO DE CARGA'!$I$2:$I$702 )="", "", _xlfn.XLOOKUP( B12, 'LOCALIZAÇÃO DE CARGA'!$A$2:$A$702, 'LOCALIZAÇÃO DE CARGA'!$I$2:$I$702 ) ), "" ) -> LGCAJ | H12: =IFERROR( IF( _xlfn.XLOOKUP( B12, 'LOCALIZAÇÃO DE CARGA'!$A$2:$A$702, 'LOCALIZAÇÃO DE CARGA'!$F$2:$F$702 )="", "", _xlfn.XLOOKUP( B12, 'LOCALIZAÇÃO DE CARGA'!$A$2:$A$702, 'LOCALIZAÇÃO DE CARGA'!$F$2:$F$702 ) ), "" ) -> Andamento | I12: {=IFERROR( IF( INDEX( 'VISÃO LOGISTICA'!$C$2:$C$525, MATCH( TRUE, ISNUMBER(FIND(B12,'VISÃO LOGISTICA'!$A$2:$A$525)), 0 ) )="Em espera", "", INDEX( 'VISÃO LOGISTICA'!$C$2:$C$525, MATCH( TRUE, ISNUMBER(FIND(B12,'VISÃO LOGISTICA'!$A$2:$A$525)), 0 ) ) ), "" )} -> Em Viagem | J12: {=IFERROR( IF( OR( INDEX( 'VISÃO LOGISTICA'!$C$2:$C$2000, MATCH( TRUE, ISNUMBER(FIND(B12,'VISÃO LOGISTICA'!$A$2:$A$2000)), 0 ) )="Em espera", INDEX( 'VISÃO LOGISTICA'!$C$2:$C$2000, MATCH( TRUE, ISNUMBER(FIND(B12,'VISÃO LOGISTICA'!$A$2:$A$2000)), 0 ) )="" ), "", INDEX( 'VISÃO LOGISTICA'!$D$2:$D$2000, MATCH( TRUE, ISNUMBER(FIND(B12,'VISÃO LOGISTICA'!$A$2:$A$2000)), 0 ) ) ), "" )} -> QHG5687 | K12: =IFERROR( IF( _xlfn.XLOOKUP( B12, 'LOCALIZAÇÃO DE CARGA'!$A$2:$A$702, 'LOCALIZAÇÃO DE CARGA'!$E$2:$E$702)="", "", _xlfn.XLOOKUP( B12, 'LOCALIZAÇÃO DE CARGA'!$A$2:$A$702, 'LOCALIZAÇÃO DE CARGA'!$E$2:$E$702) ), "" ) -> 983763.28 | L12: {=IFERROR( _xlfn.LET( _xlpm.res,_xlfn.XLOOKUP(B12,'LOCALIZAÇÃO DE CARGA'!$A$2:$A$2000,'LOCALIZAÇÃO DE CARGA'!$G$2:$G$2000), IF(_xlpm.res="","",_xlpm.res) ), "" )} -> 46157.292 | M12: {=IFERROR( _xlfn.LET( _xlpm.load,_xlfn.XLOOKUP(B12,'LOCALIZAÇÃO DE CARGA'!$A$2:$A$2000,'LOCALIZAÇÃO DE CARGA'!$A$2:$A$2000), _xlpm.res,_xlfn.XLOOKUP(_xlpm.load,DOCUMENTOS!$A$2:$A$2000,DOCUMENTOS!$D$2:$D$2000), IF(_xlpm.res="","",_xlpm.res) ), "" )} -> 46157.292 | N12: =IFERROR(IF(M12="","",M12-TIME(1,0,0)),"") -> 46157.25 | O12: {=IFERROR( _xlfn.LET( _xlpm.res,_xlfn.XLOOKUP(B12,'LOCALIZAÇÃO DE CARGA'!$A$2:$A$2000,'LOCALIZAÇÃO DE CARGA'!$S$2:$S$2000), IF(_xlpm.res="","",_xlpm.res) ), "" )} -> 46160.292 | P12: {=IFERROR( _xlfn.LET( _xlpm.res,_xlfn.XLOOKUP(B12,'LOCALIZAÇÃO DE CARGA'!$A$2:$A$702,'LOCALIZAÇÃO DE CARGA'!$T$2:$T$702), IF(_xlpm.res="","",_xlpm.res) ), "" )} -> 46158.875 | Q12: =IFERROR( IF( _xlfn.XLOOKUP( B12, 'LOCALIZAÇÃO DE CARGA'!$A$2:$A$702, 'LOCALIZAÇÃO DE CARGA'!$K$2:$K$702 )="", "", _xlfn.XLOOKUP( B12, 'LOCALIZAÇÃO DE CARGA'!$A$2:$A$702, 'LOCALIZAÇÃO DE CARGA'!$K$2:$K$702 ) ), "" ) -> FUJIOKA ELETRO IMAGEM S/A - 74675690 | R12: =IF(Q12="","",TRIM(IFERROR(LEFT(LEFT(Q12,FIND(" - ",Q12)-1),FIND("(",LEFT(Q12,FIND(" - ",Q12)-1))-1),LEFT(Q12,FIND(" - ",Q12)-1)))) -> FUJIOKA ELETRO IMAGEM S/A | S12: {=IF(B12="","",IFERROR( INDEX( 'VISÃO LOGISTICA'!$L$2:$L$525, MATCH( TRUE, ISNUMBER(FIND(B12,'VISÃO LOGISTICA'!$A$2:$A$525)), 0 ) ), "" ))} -> SANTA CRUZ DA CONCEICAO/SP/BRASIL | T12: =IFERROR( _xlfn.LET( _xlpm.res,_xlfn.XLOOKUP(B12,'LOCALIZAÇÃO DE CARGA'!$A$2:$A$702,'LOCALIZAÇÃO DE CARGA'!$R$2:$R$702), IF(_xlpm.res="","",_xlpm.res) ), "" ) -> GOIANIA/GO/BRASIL
A13: =IF(M13="","",INT(M13)) -> 46157 | B13: 6021910 | C13: =IFERROR( IF(B13="","", IF(I13="Encerrada", "VERIFICAR SMP EM ANDAMENTO", IF(VALUE(SUBSTITUTE(K13,".",""))<100000, "DESCONSIDERA, VALOR NÃO RASTREADO", IF(AND(I13="EM VIAGEM",ISNUMBER(FIND("CAJAMAR/SP",S13))), IF(E13="Patio", "NA PENSKE - COM SMP - AGUARDANDO CARREGAMENTO", "NA PENSKE - COM SMP - AGUARDANDO SAÍDA"), IF(AND(I13="Pré-SMP",ISNUMBER(FIND("CAJAMAR/SP",S13))), IF(E13="Patio", "NA PENSKE - PRÉ-SMP - AGUARDANDO CARREGAMENTO", "NA PENSKE - PRÉ-SMP - AGUARDANDO SAÍDA"), IF(AND(I13="EM VIAGEM",ISNUMBER(FIND("ITAPOA/SC",S13))), "NA CLIF - COM SMP - AGUARDANDO SAÍDA", IF(AND(I13="Pré-SMP",ISNUMBER(FIND("ITAPOA/SC",S13))), "NA CLIF - PRÉ-SMP - AGUARDANDO SAÍDA", IF(I13="EM VIAGEM", "EM VIAGEM", IF(OR(L13="",N13=""), IF(I13="EM VIAGEM","SEM PREVISAO - COM SMP", IF(I13="Pré-SMP","SEM PREVISAO - PRÉ-SMP", "SEM PREVISAO - SEM SMP")), IF(M13>L13, IF(NOW()>N13, IF(E13="Finalizado", IF(I13="EM VIAGEM","CARREGADO - COM SMP", IF(I13="Pré-SMP","CARREGADO - PRÉ-SMP", "CARREGADO - SEM SMP")), IF(I13="EM VIAGEM","ATRASADO CARREGAMENTO - COM SMP - VERIFICAR AGENDAMENTO", IF(I13="Pré-SMP","ATRASADO CARREGAMENTO - PRÉ-SMP - VERIFICAR AGENDAMENTO", "ATRASADO CARREGAMENTO - SEM SMP - VERIFICAR AGENDAMENTO"))), IF(NOW()>L13, IF(I13="EM VIAGEM","ATRASADO ENTREGA - COM SMP - VERIFICAR AGENDAMENTO", IF(I13="Pré-SMP","ATRASADO ENTREGA - PRÉ-SMP - VERIFICAR AGENDAMENTO", "ATRASADO ENTREGA - SEM SMP - VERIFICAR AGENDAMENTO")), "OK NO PRAZO - VERIFICAR AGENDAMENTO")), IF(NOW()>L13, IF(I13="EM VIAGEM","ATRASADO ENTREGA - COM SMP", IF(I13="Pré-SMP","ATRASADO ENTREGA - PRÉ-SMP", "ATRASADO ENTREGA - SEM SMP")), IF(NOW()>N13, IF(E13="Finalizado", IF(I13="EM VIAGEM","CARREGADO - COM SMP", IF(I13="Pré-SMP","CARREGADO - PRÉ-SMP", "CARREGADO - SEM SMP")), IF(I13="EM VIAGEM","ATRASADO CARREGAMENTO - COM SMP", IF(I13="Pré-SMP","ATRASADO CARREGAMENTO - PRÉ-SMP", "ATRASADO CARREGAMENTO - SEM SMP"))), IF(L13-NOW()<=1, "ATENCAO - PROXIMO", "OK - NO PRAZO" ))))))))))))),"") -> EM VIAGEM | E13: =IFERROR( IF( _xlfn.XLOOKUP( B13, 'LOCALIZAÇÃO DE CARGA'!$A$2:$A$702, 'LOCALIZAÇÃO DE CARGA'!$D$2:$D$702 )="", "", _xlfn.XLOOKUP( B13, 'LOCALIZAÇÃO DE CARGA'!$A$2:$A$702, 'LOCALIZAÇÃO DE CARGA'!$D$2:$D$702 ) ), "" ) | F13: =IFERROR( IF( _xlfn.XLOOKUP( B13, 'LOCALIZAÇÃO DE CARGA'!$A$2:$A$702, 'LOCALIZAÇÃO DE CARGA'!$H$2:$H$702 )="", "", _xlfn.XLOOKUP( B13, 'LOCALIZAÇÃO DE CARGA'!$A$2:$A$702, 'LOCALIZAÇÃO DE CARGA'!$H$2:$H$702 ) ), "" ) -> TRANSBOCAYUV | G13: =IFERROR( IF( _xlfn.XLOOKUP( B13, 'LOCALIZAÇÃO DE CARGA'!$A$2:$A$702, 'LOCALIZAÇÃO DE CARGA'!$I$2:$I$702 )="", "", _xlfn.XLOOKUP( B13, 'LOCALIZAÇÃO DE CARGA'!$A$2:$A$702, 'LOCALIZAÇÃO DE CARGA'!$I$2:$I$702 ) ), "" ) -> LGCAJ | H13: =IFERROR( IF( _xlfn.XLOOKUP( B13, 'LOCALIZAÇÃO DE CARGA'!$A$2:$A$702, 'LOCALIZAÇÃO DE CARGA'!$F$2:$F$702 )="", "", _xlfn.XLOOKUP( B13, 'LOCALIZAÇÃO DE CARGA'!$A$2:$A$702, 'LOCALIZAÇÃO DE CARGA'!$F$2:$F$702 ) ), "" ) -> Andamento | I13: {=IFERROR( IF( INDEX( 'VISÃO LOGISTICA'!$C$2:$C$525, MATCH( TRUE, ISNUMBER(FIND(B13,'VISÃO LOGISTICA'!$A$2:$A$525)), 0 ) )="Em espera", "", INDEX( 'VISÃO LOGISTICA'!$C$2:$C$525, MATCH( TRUE, ISNUMBER(FIND(B13,'VISÃO LOGISTICA'!$A$2:$A$525)), 0 ) ) ), "" )} -> Em Viagem | J13: {=IFERROR( IF( OR( INDEX( 'VISÃO LOGISTICA'!$C$2:$C$2000, MATCH( TRUE, ISNUMBER(FIND(B13,'VISÃO LOGISTICA'!$A$2:$A$2000)), 0 ) )="Em espera", INDEX( 'VISÃO LOGISTICA'!$C$2:$C$2000, MATCH( TRUE, ISNUMBER(FIND(B13,'VISÃO LOGISTICA'!$A$2:$A$2000)), 0 ) )="" ), "", INDEX( 'VISÃO LOGISTICA'!$D$2:$D$2000, MATCH( TRUE, ISNUMBER(FIND(B13,'VISÃO LOGISTICA'!$A$2:$A$2000)), 0 ) ) ), "" )} -> LUL7I53 | K13: =IFERROR( IF( _xlfn.XLOOKUP( B13, 'LOCALIZAÇÃO DE CARGA'!$A$2:$A$702, 'LOCALIZAÇÃO DE CARGA'!$E$2:$E$702)="", "", _xlfn.XLOOKUP( B13, 'LOCALIZAÇÃO DE CARGA'!$A$2:$A$702, 'LOCALIZAÇÃO DE CARGA'!$E$2:$E$702) ), "" ) -> 962790.79 | L13: {=IFERROR( _xlfn.LET( _xlpm.res,_xlfn.XLOOKUP(B13,'LOCALIZAÇÃO DE CARGA'!$A$2:$A$2000,'LOCALIZAÇÃO DE CARGA'!$G$2:$G$2000), IF(_xlpm.res="","",_xlpm.res) ), "" )} -> 46159.783 | M13: {=IFERROR( _xlfn.LET( _xlpm.load,_xlfn.XLOOKUP(B13,'LOCALIZAÇÃO DE CARGA'!$A$2:$A$2000,'LOCALIZAÇÃO DE CARGA'!$A$2:$A$2000), _xlpm.res,_xlfn.XLOOKUP(_xlpm.load,DOCUMENTOS!$A$2:$A$2000,DOCUMENTOS!$D$2:$D$2000), IF(_xlpm.res="","",_xlpm.res) ), "" )} -> 46157.708 | N13: =IFERROR(IF(M13="","",M13-TIME(1,0,0)),"") -> 46157.667 | O13: {=IFERROR( _xlfn.LET( _xlpm.res,_xlfn.XLOOKUP(B13,'LOCALIZAÇÃO DE CARGA'!$A$2:$A$2000,'LOCALIZAÇÃO DE CARGA'!$S$2:$S$2000), IF(_xlpm.res="","",_xlpm.res) ), "" )} -> 46160.25 | P13: {=IFERROR( _xlfn.LET( _xlpm.res,_xlfn.XLOOKUP(B13,'LOCALIZAÇÃO DE CARGA'!$A$2:$A$702,'LOCALIZAÇÃO DE CARGA'!$T$2:$T$702), IF(_xlpm.res="","",_xlpm.res) ), "" )} -> 46158.622 | Q13: =IFERROR( IF( _xlfn.XLOOKUP( B13, 'LOCALIZAÇÃO DE CARGA'!$A$2:$A$702, 'LOCALIZAÇÃO DE CARGA'!$K$2:$K$702 )="", "", _xlfn.XLOOKUP( B13, 'LOCALIZAÇÃO DE CARGA'!$A$2:$A$702, 'LOCALIZAÇÃO DE CARGA'!$K$2:$K$702 ) ), "" ) -> GRUPO CASAS BAHIA S.A(CD1401) - 25255030 | R13: =IF(Q13="","",TRIM(IFERROR(LEFT(LEFT(Q13,FIND(" - ",Q13)-1),FIND("(",LEFT(Q13,FIND(" - ",Q13)-1))-1),LEFT(Q13,FIND(" - ",Q13)-1)))) -> GRUPO CASAS BAHIA S.A | S13: {=IF(B13="","",IFERROR( INDEX( 'VISÃO LOGISTICA'!$L$2:$L$525, MATCH( TRUE, ISNUMBER(FIND(B13,'VISÃO LOGISTICA'!$A$2:$A$525)), 0 ) ), "" ))} -> ROSEIRA/SP/BRASIL | T13: =IFERROR( _xlfn.LET( _xlpm.res,_xlfn.XLOOKUP(B13,'LOCALIZAÇÃO DE CARGA'!$A$2:$A$702,'LOCALIZAÇÃO DE CARGA'!$R$2:$R$702), IF(_xlpm.res="","",_xlpm.res) ), "" ) -> DUQUE DE CAXIAS/RJ/BRASIL
